<?xml version="1.0" ?>
<sdf version='1.6'>
  <world name='default'>
    <light name='sun' type='directional'>
      <cast_shadows>1</cast_shadows>
      <pose frame=''>0 0 10 0 -0 0</pose>
      <diffuse>0.8 0.8 0.8 1</diffuse>
      <specular>0.2 0.2 0.2 1</specular>
      <attenuation>
        <range>1000</range>
        <constant>0.9</constant>
        <linear>0.01</linear>
        <quadratic>0.001</quadratic>
      </attenuation>
      <direction>-0.5 0.1 -0.9</direction>
    </light>
    <model name='ground_plane'>
      <static>1</static>
      <link name='link'>
        <collision name='collision'>
          <geometry>
            <plane>
              <normal>0 0 1</normal>
              <size>100 100</size>
            </plane>
          </geometry>
          <surface>
            <contact>
              <collide_bitmask>65535</collide_bitmask>
              <ode/>
            </contact>
            <friction>
              <ode>
                <mu>100</mu>
                <mu2>50</mu2>
              </ode>
              <torsional>
                <ode/>
              </torsional>
            </friction>
            <bounce/>
          </surface>
          <max_contacts>10</max_contacts>
        </collision>
        <visual name='visual'>
          <cast_shadows>0</cast_shadows>
          <geometry>
            <plane>
              <normal>0 0 1</normal>
              <size>100 100</size>
            </plane>
          </geometry>
          <material>
            <script>
              <uri>file://media/materials/scripts/gazebo.material</uri>
              <name>Gazebo/Grey</name>
            </script>
          </material>
        </visual>
        <self_collide>0</self_collide>
        <enable_wind>0</enable_wind>
        <kinematic>0</kinematic>
      </link>
    </model>
    <gravity>0 0 -9.8</gravity>
    <magnetic_field>6e-06 2.3e-05 -4.2e-05</magnetic_field>
    <atmosphere type='adiabatic'/>
    <physics name='default_physics' default='0' type='ode'>
      <max_step_size>0.001</max_step_size>
      <real_time_factor>1</real_time_factor>
      <real_time_update_rate>1000</real_time_update_rate>
    </physics>
    <scene>
      <ambient>0.4 0.4 0.4 1</ambient>
      <background>0.7 0.7 0.7 1</background>
      <shadows>1</shadows>
    </scene>
    <audio>
      <device>default</device>
    </audio>
    <wind/>
    <spherical_coordinates>
      <surface_model>EARTH_WGS84</surface_model>
      <latitude_deg>0</latitude_deg>
      <longitude_deg>0</longitude_deg>
      <elevation>0</elevation>
      <heading_deg>0</heading_deg>
    </spherical_coordinates>
    <model name='bunker'>
      <link name='robot_base'>
        <pose frame=''>0 0 0 0 -0 0</pose>
        <inertial>
          <pose frame=''>0.021241 0.004755 -0.127581 0 -0 0</pose>
          <mass>0.0001</mass>
          <inertia>
            <ixx>0.607716</ixx>
            <ixy>1.92178e-05</ixy>
            <ixz>-0.0365321</ixz>
            <iyy>1.70041</iyy>
            <iyz>2.16963e-05</iyz>
            <izz>1.84232</izz>
          </inertia>
        </inertial>
        <collision name='robot_base_collision'>
          <pose frame=''>0.53 -0.392 -0.358 1.57 0 3.14</pose>
          <geometry>
            <mesh>
              <scale>0.001 0.001 0.001</scale>
              <uri>/home/parlab/github/bunker_eplorer_ws/src/bunker_explorer_ws/ugv_gazebo_sim/bunker/bunker_description/meshes/BUNKER.STL</uri>
            </mesh>
          </geometry>
          <surface>
            <contact>
              <ode/>
            </contact>
            <friction>
              <ode/>
              <torsional>
                <ode/>
              </torsional>
            </friction>
            <bounce/>
          </surface>
          <max_contacts>10</max_contacts>
        </collision>
        <collision name='robot_base_fixed_joint_lump__camera_link_collision_1'>
          <pose frame=''>0.333 0 0.297 0 -0 0</pose>
          <geometry>
            <box>
              <size>0.012 0.132 0.02</size>
            </box>
          </geometry>
          <max_contacts>10</max_contacts>
          <surface>
            <contact>
              <ode/>
            </contact>
            <bounce/>
            <friction>
              <torsional>
                <ode/>
              </torsional>
              <ode/>
            </friction>
          </surface>
        </collision>
        <visual name='robot_base_visual'>
          <pose frame=''>0.53 -0.392 -0.358 1.57 0 3.14</pose>
          <geometry>
            <mesh>
              <scale>0.001 0.001 0.001</scale>
              <uri>/home/parlab/github/bunker_eplorer_ws/src/bunker_explorer_ws/ugv_gazebo_sim/bunker/bunker_description/meshes/BUNKER.STL</uri>
            </mesh>
          </geometry>
          <material>
            <script>
              <name>Gazebo/Gray</name>
              <uri>file://media/materials/scripts/gazebo.material</uri>
            </script>
          </material>
        </visual>
        <visual name='robot_base_fixed_joint_lump__rbot_base2_visual_1'>
          <pose frame=''>0.3 0 0 0 -0 0</pose>
          <geometry>
            <box>
              <size>0.045 0.09 0.03</size>
            </box>
          </geometry>
        </visual>
        <visual name='robot_base_fixed_joint_lump__servo_bottom2_visual_2'>
          <pose frame=''>0.3 0 0.14 0 -0 0</pose>
          <geometry>
            <cylinder>
              <length>0.25</length>
              <radius>0.015</radius>
            </cylinder>
          </geometry>
        </visual>
        <visual name='robot_base_fixed_joint_lump__up_mount2_visual_3'>
          <pose frame=''>0.3 0 0.29 0 -0 0</pose>
          <geometry>
            <box>
              <size>0.05 0.148 0.05</size>
            </box>
          </geometry>
        </visual>
        <visual name='robot_base_fixed_joint_lump__camera_link_visual_4'>
          <pose frame=''>0.33 -0.065 0.29 1.57 -0 1.57</pose>
          <geometry>
            <mesh>
              <scale>1 1 1</scale>
              <uri>/home/parlab/github/bunker_eplorer_ws/src/bunker_explorer_ws/ugv_gazebo_sim/bunker/bunker_description/meshes/sensors/r200.dae</uri>
            </mesh>
          </geometry>
        </visual>
        <visual name='robot_base_fixed_joint_lump__rbot_base3_visual_5'>
          <pose frame=''>-0.25 0 0 0 -0 0</pose>
          <geometry>
            <box>
              <size>0.045 0.09 0.03</size>
            </box>
          </geometry>
        </visual>
        <visual name='robot_base_fixed_joint_lump__servo_bottom3_visual_6'>
          <pose frame=''>-0.25 0 0.14 0 -0 0</pose>
          <geometry>
            <cylinder>
              <length>0.25</length>
              <radius>0.015</radius>
            </cylinder>
          </geometry>
        </visual>
        <visual name='robot_base_fixed_joint_lump__up_mount3_visual_7'>
          <pose frame=''>-0.25 0 0.29 0 -0 0</pose>
          <geometry>
            <box>
              <size>0.05 0.148 0.05</size>
            </box>
          </geometry>
        </visual>
        <visual name='robot_base_fixed_joint_lump__gps_link_visual_8'>
          <pose frame=''>-0.25 0 0.29 0 -0 0</pose>
          <geometry>
            <cylinder>
              <length>0.065</length>
              <radius>0.075</radius>
            </cylinder>
          </geometry>
        </visual>
        <velocity_decay/>
        <gravity>1</gravity>
        <velocity_decay/>
        <sensor name='realsense_R200' type='depth'>
          <always_on>1</always_on>
          <visualize>0</visualize>
          <camera name='__default__'>
            <horizontal_fov>1.3439</horizontal_fov>
            <image>
              <width>1920</width>
              <height>1080</height>
              <format>R8G8B8</format>
            </image>
            <depth_camera>
              <output>depths</output>
            </depth_camera>
            <clip>
              <near>0.03</near>
              <far>100</far>
            </clip>
          </camera>
          <plugin name='camera_controller' filename='libgazebo_ros_openni_kinect.so'>
            <baseline>0.2</baseline>
            <alwaysOn>1</alwaysOn>
            <updateRate>30.0</updateRate>
            <cameraName>camera</cameraName>
            <frameName>camera_rgb_optical_frame</frameName>
            <imageTopicName>rgb/image_raw</imageTopicName>
            <depthImageTopicName>depth/image_raw</depthImageTopicName>
            <pointCloudTopicName>depth/points</pointCloudTopicName>
            <cameraInfoTopicName>rgb/camera_info</cameraInfoTopicName>
            <depthImageCameraInfoTopicName>depth/camera_info</depthImageCameraInfoTopicName>
            <pointCloudCutoff>0.4</pointCloudCutoff>
            <hackBaseline>0.07</hackBaseline>
            <distortionK1>0.0</distortionK1>
            <distortionK2>0.0</distortionK2>
            <distortionK3>0.0</distortionK3>
            <distortionT1>0.0</distortionT1>
            <distortionT2>0.0</distortionT2>
            <CxPrime>0.0</CxPrime>
            <Cx>0.0</Cx>
            <Cy>0.0</Cy>
            <focalLength>0</focalLength>
            <hackBaseline>0</hackBaseline>
            <robotNamespace>/</robotNamespace>
          </plugin>
          <pose frame=''>0.335 -0.047 0.303 0 -0 0</pose>
        </sensor>
        <self_collide>0</self_collide>
        <enable_wind>0</enable_wind>
        <kinematic>0</kinematic>
      </link>
      <link name='wheel1.1_Link'>
        <pose frame=''>0.37551 0.3495 -0.22305 1.5708 -0 3.14159</pose>
        <inertial>
          <pose frame=''>-0 0 -0.072 0 -0 0</pose>
          <mass>0.0001</mass>
          <inertia>
            <ixx>6.58751e-05</ixx>
            <ixy>-1.46559e-09</ixy>
            <ixz>-8.34967e-12</ixz>
            <iyy>6.58796e-05</iyy>
            <iyz>-2.4786e-12</iyz>
            <izz>0.000112722</izz>
          </inertia>
        </inertial>
        <collision name='wheel1.1_Link_collision'>
          <pose frame=''>0 0 0 0 -0 0</pose>
          <geometry>
            <mesh>
              <scale>1 1 1</scale>
              <uri>/home/parlab/github/bunker_eplorer_ws/src/bunker_explorer_ws/ugv_gazebo_sim/bunker/bunker_description/meshes/wheel1.1_Link.STL</uri>
            </mesh>
          </geometry>
          <max_contacts>10</max_contacts>
          <surface>
            <contact>
              <ode/>
            </contact>
            <bounce/>
            <friction>
              <torsional>
                <ode/>
              </torsional>
              <ode/>
            </friction>
          </surface>
        </collision>
        <visual name='wheel1.1_Link_visual'>
          <pose frame=''>0 0 0 0 -0 0</pose>
          <geometry>
            <mesh>
              <scale>1 1 1</scale>
              <uri>/home/parlab/github/bunker_eplorer_ws/src/bunker_explorer_ws/ugv_gazebo_sim/bunker/bunker_description/meshes/wheel1.1_Link.STL</uri>
            </mesh>
          </geometry>
        </visual>
        <self_collide>0</self_collide>
        <enable_wind>0</enable_wind>
        <kinematic>0</kinematic>
      </link>
      <joint name='wheel1.1_jont' type='revolute'>
        <child>wheel1.1_Link</child>
        <parent>robot_base</parent>
        <axis>
          <xyz>7e-06 1 -4e-06</xyz>
          <limit>
            <lower>-180</lower>
            <upper>180</upper>
            <effort>0</effort>
            <velocity>0</velocity>
          </limit>
          <dynamics>
            <spring_reference>0</spring_reference>
            <spring_stiffness>0</spring_stiffness>
          </dynamics>
          <use_parent_model_frame>1</use_parent_model_frame>
        </axis>
      </joint>
      <link name='wheel1.2_Link'>
        <pose frame=''>0.29039 0.3495 -0.28104 1.5708 -0 3.14159</pose>
        <inertial>
          <pose frame=''>0 0 -0.072 0 -0 0</pose>
          <mass>0.0001</mass>
          <inertia>
            <ixx>0.000179574</ixx>
            <ixy>1.15789e-20</ixy>
            <ixz>1.35634e-21</ixz>
            <iyy>0.000179574</iyy>
            <iyz>6.03698e-23</iyz>
            <izz>0.000332595</izz>
          </inertia>
        </inertial>
        <collision name='wheel1.2_Link_collision'>
          <pose frame=''>0 0 0 0 -0 0</pose>
          <geometry>
            <mesh>
              <scale>1 1 1</scale>
              <uri>/home/parlab/github/bunker_eplorer_ws/src/bunker_explorer_ws/ugv_gazebo_sim/bunker/bunker_description/meshes/wheel1.2_Link.STL</uri>
            </mesh>
          </geometry>
          <max_contacts>10</max_contacts>
          <surface>
            <contact>
              <ode/>
            </contact>
            <bounce/>
            <friction>
              <torsional>
                <ode/>
              </torsional>
              <ode/>
            </friction>
          </surface>
        </collision>
        <visual name='wheel1.2_Link_visual'>
          <pose frame=''>0 0 0 0 -0 0</pose>
          <geometry>
            <mesh>
              <scale>1 1 1</scale>
              <uri>/home/parlab/github/bunker_eplorer_ws/src/bunker_explorer_ws/ugv_gazebo_sim/bunker/bunker_description/meshes/wheel1.2_Link.STL</uri>
            </mesh>
          </geometry>
        </visual>
        <self_collide>0</self_collide>
        <enable_wind>0</enable_wind>
        <kinematic>0</kinematic>
      </link>
      <joint name='wheel1.2_joint' type='revolute'>
        <child>wheel1.2_Link</child>
        <parent>robot_base</parent>
        <axis>
          <xyz>7e-06 1 -4e-06</xyz>
          <limit>
            <lower>-180</lower>
            <upper>180</upper>
            <effort>0</effort>
            <velocity>0</velocity>
          </limit>
          <dynamics>
            <spring_reference>0</spring_reference>
            <spring_stiffness>0</spring_stiffness>
          </dynamics>
          <use_parent_model_frame>1</use_parent_model_frame>
        </axis>
      </joint>
      <link name='wheel1.3_Link'>
        <pose frame=''>0.29603 0.3495 -0.087 1.5708 -0 3.14159</pose>
        <inertial>
          <pose frame=''>3.4e-05 -2.7e-05 -0.07015 0 -0 0</pose>
          <mass>0.0001</mass>
          <inertia>
            <ixx>0.000105254</ixx>
            <ixy>1.32328e-08</ixy>
            <ixz>3.84295e-11</ixz>
            <iyy>0.000105249</iyy>
            <iyz>-1.41156e-11</iyz>
            <izz>0.000173281</izz>
          </inertia>
        </inertial>
        <collision name='wheel1.3_Link_collision'>
          <pose frame=''>0 0 0 0 -0 0</pose>
          <geometry>
            <mesh>
              <scale>1 1 1</scale>
              <uri>/home/parlab/github/bunker_eplorer_ws/src/bunker_explorer_ws/ugv_gazebo_sim/bunker/bunker_description/meshes/wheel1.3_Link.STL</uri>
            </mesh>
          </geometry>
          <max_contacts>10</max_contacts>
          <surface>
            <contact>
              <ode/>
            </contact>
            <bounce/>
            <friction>
              <torsional>
                <ode/>
              </torsional>
              <ode/>
            </friction>
          </surface>
        </collision>
        <visual name='wheel1.3_Link_visual'>
          <pose frame=''>0 0 0 0 -0 0</pose>
          <geometry>
            <mesh>
              <scale>1 1 1</scale>
              <uri>/home/parlab/github/bunker_eplorer_ws/src/bunker_explorer_ws/ugv_gazebo_sim/bunker/bunker_description/meshes/wheel1.3_Link.STL</uri>
            </mesh>
          </geometry>
        </visual>
        <self_collide>0</self_collide>
        <enable_wind>0</enable_wind>
        <kinematic>0</kinematic>
      </link>
      <joint name='wheel1.3_joint' type='revolute'>
        <child>wheel1.3_Link</child>
        <parent>robot_base</parent>
        <axis>
          <xyz>-7e-06 -1 4e-06</xyz>
          <limit>
            <lower>-180</lower>
            <upper>180</upper>
            <effort>0</effort>
            <velocity>0</velocity>
          </limit>
          <dynamics>
            <spring_reference>0</spring_reference>
            <spring_stiffness>0</spring_stiffness>
          </dynamics>
          <use_parent_model_frame>1</use_parent_model_frame>
        </axis>
      </joint>
      <link name='wheel1_Link'>
        <pose frame=''>0.44403 0.3495 -0.12853 1.5708 -0 3.14159</pose>
        <inertial>
          <pose frame=''>0 -0 -0.072 0 -0 0</pose>
          <mass>0.0001</mass>
          <inertia>
            <ixx>0.000378441</ixx>
            <ixy>5.60823e-21</ixy>
            <ixz>3.04208e-20</ixz>
            <iyy>0.000378441</iyy>
            <iyz>-7.56627e-21</iyz>
            <izz>0.000710151</izz>
          </inertia>
        </inertial>
        <collision name='wheel1_Link_collision'>
          <pose frame=''>0 0 0 0 -0 0</pose>
          <geometry>
            <mesh>
              <scale>1 1 1</scale>
              <uri>/home/parlab/github/bunker_eplorer_ws/src/bunker_explorer_ws/ugv_gazebo_sim/bunker/bunker_description/meshes/wheel1_Link.STL</uri>
            </mesh>
          </geometry>
          <max_contacts>10</max_contacts>
          <surface>
            <contact>
              <ode/>
            </contact>
            <bounce/>
            <friction>
              <torsional>
                <ode/>
              </torsional>
              <ode/>
            </friction>
          </surface>
        </collision>
        <visual name='wheel1_Link_visual'>
          <pose frame=''>0 0 0 0 -0 0</pose>
          <geometry>
            <mesh>
              <scale>1 1 1</scale>
              <uri>/home/parlab/github/bunker_eplorer_ws/src/bunker_explorer_ws/ugv_gazebo_sim/bunker/bunker_description/meshes/wheel1_Link.STL</uri>
            </mesh>
          </geometry>
        </visual>
        <self_collide>0</self_collide>
        <enable_wind>0</enable_wind>
        <kinematic>0</kinematic>
      </link>
      <joint name='wheel1_joint' type='revolute'>
        <child>wheel1_Link</child>
        <parent>robot_base</parent>
        <axis>
          <xyz>7e-06 1 -4e-06</xyz>
          <limit>
            <lower>-180</lower>
            <upper>180</upper>
            <effort>0</effort>
            <velocity>0</velocity>
          </limit>
          <dynamics>
            <spring_reference>0</spring_reference>
            <spring_stiffness>0</spring_stiffness>
          </dynamics>
          <use_parent_model_frame>1</use_parent_model_frame>
        </axis>
      </joint>
      <link name='wheel2.1_Link'>
        <pose frame=''>0.37551 -0.3495 -0.22305 1.5708 -0 3.14159</pose>
        <inertial>
          <pose frame=''>-0 0 0.072 0 -0 0</pose>
          <mass>0.0001</mass>
          <inertia>
            <ixx>6.58751e-05</ixx>
            <ixy>-1.46559e-09</ixy>
            <ixz>-8.34967e-12</ixz>
            <iyy>6.58796e-05</iyy>
            <iyz>-2.4786e-12</iyz>
            <izz>0.000112722</izz>
          </inertia>
        </inertial>
        <collision name='wheel2.1_Link_collision'>
          <pose frame=''>0 0 0 0 -0 0</pose>
          <geometry>
            <mesh>
              <scale>1 1 1</scale>
              <uri>/home/parlab/github/bunker_eplorer_ws/src/bunker_explorer_ws/ugv_gazebo_sim/bunker/bunker_description/meshes/wheel2.1_Link.STL</uri>
            </mesh>
          </geometry>
          <max_contacts>10</max_contacts>
          <surface>
            <contact>
              <ode/>
            </contact>
            <bounce/>
            <friction>
              <torsional>
                <ode/>
              </torsional>
              <ode/>
            </friction>
          </surface>
        </collision>
        <visual name='wheel2.1_Link_visual'>
          <pose frame=''>0 0 0 0 -0 0</pose>
          <geometry>
            <mesh>
              <scale>1 1 1</scale>
              <uri>/home/parlab/github/bunker_eplorer_ws/src/bunker_explorer_ws/ugv_gazebo_sim/bunker/bunker_description/meshes/wheel2.1_Link.STL</uri>
            </mesh>
          </geometry>
        </visual>
        <self_collide>0</self_collide>
        <enable_wind>0</enable_wind>
        <kinematic>0</kinematic>
      </link>
      <joint name='wheel2.1_joint' type='revolute'>
        <child>wheel2.1_Link</child>
        <parent>robot_base</parent>
        <axis>
          <xyz>-7e-06 -1 4e-06</xyz>
          <limit>
            <lower>-180</lower>
            <upper>180</upper>
            <effort>0</effort>
            <velocity>0</velocity>
          </limit>
          <dynamics>
            <spring_reference>0</spring_reference>
            <spring_stiffness>0</spring_stiffness>
          </dynamics>
          <use_parent_model_frame>1</use_parent_model_frame>
        </axis>
      </joint>
      <link name='wheel2.2_Link'>
        <pose frame=''>0.29039 -0.3495 -0.28104 1.5708 -0 3.14159</pose>
        <inertial>
          <pose frame=''>-0 -0 0.072 0 -0 0</pose>
          <mass>0.0001</mass>
          <inertia>
            <ixx>0.000179574</ixx>
            <ixy>6.2896e-21</ixy>
            <ixz>2.14011e-21</ixz>
            <iyy>0.000179574</iyy>
            <iyz>1.2771e-22</iyz>
            <izz>0.000332595</izz>
          </inertia>
        </inertial>
        <collision name='wheel2.2_Link_collision'>
          <pose frame=''>0 0 0 0 -0 0</pose>
          <geometry>
            <mesh>
              <scale>1 1 1</scale>
              <uri>/home/parlab/github/bunker_eplorer_ws/src/bunker_explorer_ws/ugv_gazebo_sim/bunker/bunker_description/meshes/wheel2.2_Link.STL</uri>
            </mesh>
          </geometry>
          <max_contacts>10</max_contacts>
          <surface>
            <contact>
              <ode/>
            </contact>
            <bounce/>
            <friction>
              <torsional>
                <ode/>
              </torsional>
              <ode/>
            </friction>
          </surface>
        </collision>
        <visual name='wheel2.2_Link_visual'>
          <pose frame=''>0 0 0 0 -0 0</pose>
          <geometry>
            <mesh>
              <scale>1 1 1</scale>
              <uri>/home/parlab/github/bunker_eplorer_ws/src/bunker_explorer_ws/ugv_gazebo_sim/bunker/bunker_description/meshes/wheel2.2_Link.STL</uri>
            </mesh>
          </geometry>
        </visual>
        <self_collide>0</self_collide>
        <enable_wind>0</enable_wind>
        <kinematic>0</kinematic>
      </link>
      <joint name='wheel2.2_joint' type='revolute'>
        <child>wheel2.2_Link</child>
        <parent>robot_base</parent>
        <axis>
          <xyz>-7e-06 -1 4e-06</xyz>
          <limit>
            <lower>-180</lower>
            <upper>180</upper>
            <effort>0</effort>
            <velocity>0</velocity>
          </limit>
          <dynamics>
            <spring_reference>0</spring_reference>
            <spring_stiffness>0</spring_stiffness>
          </dynamics>
          <use_parent_model_frame>1</use_parent_model_frame>
        </axis>
      </joint>
      <link name='wheel2.3_Link'>
        <pose frame=''>0.29603 -0.3495 -0.087 1.5708 -0 3.14159</pose>
        <inertial>
          <pose frame=''>3.5e-05 -2.7e-05 0.070928 0 -0 0</pose>
          <mass>0.0001</mass>
          <inertia>
            <ixx>0.000105035</ixx>
            <ixy>1.32328e-08</ixy>
            <ixz>3.84295e-11</ixz>
            <iyy>0.00010503</iyy>
            <iyz>-1.41156e-11</iyz>
            <izz>0.000172982</izz>
          </inertia>
        </inertial>
        <collision name='wheel2.3_Link_collision'>
          <pose frame=''>0 0 0 0 -0 0</pose>
          <geometry>
            <mesh>
              <scale>1 1 1</scale>
              <uri>/home/parlab/github/bunker_eplorer_ws/src/bunker_explorer_ws/ugv_gazebo_sim/bunker/bunker_description/meshes/wheel2.3_Link.STL</uri>
            </mesh>
          </geometry>
          <max_contacts>10</max_contacts>
          <surface>
            <contact>
              <ode/>
            </contact>
            <bounce/>
            <friction>
              <torsional>
                <ode/>
              </torsional>
              <ode/>
            </friction>
          </surface>
        </collision>
        <visual name='wheel2.3_Link_visual'>
          <pose frame=''>0 0 0 0 -0 0</pose>
          <geometry>
            <mesh>
              <scale>1 1 1</scale>
              <uri>/home/parlab/github/bunker_eplorer_ws/src/bunker_explorer_ws/ugv_gazebo_sim/bunker/bunker_description/meshes/wheel2.3_Link.STL</uri>
            </mesh>
          </geometry>
        </visual>
        <self_collide>0</self_collide>
        <enable_wind>0</enable_wind>
        <kinematic>0</kinematic>
      </link>
      <joint name='wheel2.3_joint' type='revolute'>
        <child>wheel2.3_Link</child>
        <parent>robot_base</parent>
        <axis>
          <xyz>7e-06 1 -4e-06</xyz>
          <limit>
            <lower>-180</lower>
            <upper>180</upper>
            <effort>0</effort>
            <velocity>0</velocity>
          </limit>
          <dynamics>
            <spring_reference>0</spring_reference>
            <spring_stiffness>0</spring_stiffness>
          </dynamics>
          <use_parent_model_frame>1</use_parent_model_frame>
        </axis>
      </joint>
      <link name='wheel2_Link'>
        <pose frame=''>0.44403 -0.3495 -0.12853 1.5708 -0 3.14159</pose>
        <inertial>
          <pose frame=''>-0 0 0.072 0 -0 0</pose>
          <mass>0.0001</mass>
          <inertia>
            <ixx>0.000378441</ixx>
            <ixy>3.37302e-21</ixy>
            <ixz>2.71827e-20</ixz>
            <iyy>0.000378441</iyy>
            <iyz>-7.32822e-21</iyz>
            <izz>0.000710151</izz>
          </inertia>
        </inertial>
        <collision name='wheel2_Link_collision'>
          <pose frame=''>0 0 0 0 -0 0</pose>
          <geometry>
            <mesh>
              <scale>1 1 1</scale>
              <uri>/home/parlab/github/bunker_eplorer_ws/src/bunker_explorer_ws/ugv_gazebo_sim/bunker/bunker_description/meshes/wheel2_Link.STL</uri>
            </mesh>
          </geometry>
          <max_contacts>10</max_contacts>
          <surface>
            <contact>
              <ode/>
            </contact>
            <bounce/>
            <friction>
              <torsional>
                <ode/>
              </torsional>
              <ode/>
            </friction>
          </surface>
        </collision>
        <visual name='wheel2_Link_visual'>
          <pose frame=''>0 0 0 0 -0 0</pose>
          <geometry>
            <mesh>
              <scale>1 1 1</scale>
              <uri>/home/parlab/github/bunker_eplorer_ws/src/bunker_explorer_ws/ugv_gazebo_sim/bunker/bunker_description/meshes/wheel2_Link.STL</uri>
            </mesh>
          </geometry>
        </visual>
        <self_collide>0</self_collide>
        <enable_wind>0</enable_wind>
        <kinematic>0</kinematic>
      </link>
      <joint name='wheel2_joint' type='revolute'>
        <child>wheel2_Link</child>
        <parent>robot_base</parent>
        <axis>
          <xyz>-7e-06 -1 4e-06</xyz>
          <limit>
            <lower>-180</lower>
            <upper>180</upper>
            <effort>0</effort>
            <velocity>0</velocity>
          </limit>
          <dynamics>
            <spring_reference>0</spring_reference>
            <spring_stiffness>0</spring_stiffness>
          </dynamics>
          <use_parent_model_frame>1</use_parent_model_frame>
        </axis>
      </joint>
      <link name='wheel3.1_Link'>
        <pose frame=''>-0.23111 0.3495 -0.27671 1.5708 -0 3.14159</pose>
        <inertial>
          <pose frame=''>0 0 -0.072 0 -0 0</pose>
          <mass>0.0001</mass>
          <inertia>
            <ixx>0.000179574</ixx>
            <ixy>-1.73824e-20</ixy>
            <ixz>-2.5316e-21</ixz>
            <iyy>0.000179574</iyy>
            <iyz>-3.13741e-21</iyz>
            <izz>0.000332595</izz>
          </inertia>
        </inertial>
        <collision name='wheel3.1_Link_collision'>
          <pose frame=''>0 0 0 0 -0 0</pose>
          <geometry>
            <mesh>
              <scale>1 1 1</scale>
              <uri>/home/parlab/github/bunker_eplorer_ws/src/bunker_explorer_ws/ugv_gazebo_sim/bunker/bunker_description/meshes/wheel3.1_Link.STL</uri>
            </mesh>
          </geometry>
          <max_contacts>10</max_contacts>
          <surface>
            <contact>
              <ode/>
            </contact>
            <bounce/>
            <friction>
              <torsional>
                <ode/>
              </torsional>
              <ode/>
            </friction>
          </surface>
        </collision>
        <visual name='wheel3.1_Link_visual'>
          <pose frame=''>0 0 0 0 -0 0</pose>
          <geometry>
            <mesh>
              <scale>1 1 1</scale>
              <uri>/home/parlab/github/bunker_eplorer_ws/src/bunker_explorer_ws/ugv_gazebo_sim/bunker/bunker_description/meshes/wheel3.1_Link.STL</uri>
            </mesh>
          </geometry>
        </visual>
        <self_collide>0</self_collide>
        <enable_wind>0</enable_wind>
        <kinematic>0</kinematic>
      </link>
      <joint name='wheel3.1_joint' type='revolute'>
        <child>wheel3.1_Link</child>
        <parent>robot_base</parent>
        <axis>
          <xyz>7e-06 1 -4e-06</xyz>
          <limit>
            <lower>-180</lower>
            <upper>180</upper>
            <effort>0</effort>
            <velocity>0</velocity>
          </limit>
          <dynamics>
            <spring_reference>0</spring_reference>
            <spring_stiffness>0</spring_stiffness>
          </dynamics>
          <use_parent_model_frame>1</use_parent_model_frame>
        </axis>
      </joint>
      <link name='wheel3.2_Link'>
        <pose frame=''>0.043885 0.3495 -0.27671 1.5708 -0 3.14159</pose>
        <inertial>
          <pose frame=''>0 0 -0.072 0 -0 0</pose>
          <mass>0.0001</mass>
          <inertia>
            <ixx>0.000179574</ixx>
            <ixy>9.82929e-22</ixy>
            <ixz>1.1099e-21</ixz>
            <iyy>0.000179574</iyy>
            <iyz>-4.81322e-21</iyz>
            <izz>0.000332595</izz>
          </inertia>
        </inertial>
        <collision name='wheel3.2_Link_collision'>
          <pose frame=''>0 0 0 0 -0 0</pose>
          <geometry>
            <mesh>
              <scale>1 1 1</scale>
              <uri>/home/parlab/github/bunker_eplorer_ws/src/bunker_explorer_ws/ugv_gazebo_sim/bunker/bunker_description/meshes/wheel3.2_Link.STL</uri>
            </mesh>
          </geometry>
          <max_contacts>10</max_contacts>
          <surface>
            <contact>
              <ode/>
            </contact>
            <bounce/>
            <friction>
              <torsional>
                <ode/>
              </torsional>
              <ode/>
            </friction>
          </surface>
        </collision>
        <visual name='wheel3.2_Link_visual'>
          <pose frame=''>0 0 0 0 -0 0</pose>
          <geometry>
            <mesh>
              <scale>1 1 1</scale>
              <uri>/home/parlab/github/bunker_eplorer_ws/src/bunker_explorer_ws/ugv_gazebo_sim/bunker/bunker_description/meshes/wheel3.2_Link.STL</uri>
            </mesh>
          </geometry>
        </visual>
        <self_collide>0</self_collide>
        <enable_wind>0</enable_wind>
        <kinematic>0</kinematic>
      </link>
      <joint name='wheel3.2_joint' type='revolute'>
        <child>wheel3.2_Link</child>
        <parent>robot_base</parent>
        <axis>
          <xyz>7e-06 1 -4e-06</xyz>
          <limit>
            <lower>-180</lower>
            <upper>180</upper>
            <effort>0</effort>
            <velocity>0</velocity>
          </limit>
          <dynamics>
            <spring_reference>0</spring_reference>
            <spring_stiffness>0</spring_stiffness>
          </dynamics>
          <use_parent_model_frame>1</use_parent_model_frame>
        </axis>
      </joint>
      <link name='wheel3.3_Link'>
        <pose frame=''>-0.28597 0.3495 -0.087 1.5708 -0 3.14159</pose>
        <inertial>
          <pose frame=''>0 -5.3e-05 -0.07015 0 -0 0</pose>
          <mass>0.0001</mass>
          <inertia>
            <ixx>0.000105265</ixx>
            <ixy>7.98232e-12</ixy>
            <ixz>6.804e-11</ixz>
            <iyy>0.000105238</iyy>
            <iyz>-2.72106e-11</iyz>
            <izz>0.000173281</izz>
          </inertia>
        </inertial>
        <collision name='wheel3.3_Link_collision'>
          <pose frame=''>0 0 0 0 -0 0</pose>
          <geometry>
            <mesh>
              <scale>1 1 1</scale>
              <uri>/home/parlab/github/bunker_eplorer_ws/src/bunker_explorer_ws/ugv_gazebo_sim/bunker/bunker_description/meshes/wheel3.3_Link.STL</uri>
            </mesh>
          </geometry>
          <max_contacts>10</max_contacts>
          <surface>
            <contact>
              <ode/>
            </contact>
            <bounce/>
            <friction>
              <torsional>
                <ode/>
              </torsional>
              <ode/>
            </friction>
          </surface>
        </collision>
        <visual name='wheel3.3_Link_visual'>
          <pose frame=''>0 0 0 0 -0 0</pose>
          <geometry>
            <mesh>
              <scale>1 1 1</scale>
              <uri>/home/parlab/github/bunker_eplorer_ws/src/bunker_explorer_ws/ugv_gazebo_sim/bunker/bunker_description/meshes/wheel3.3_Link.STL</uri>
            </mesh>
          </geometry>
        </visual>
        <self_collide>0</self_collide>
        <enable_wind>0</enable_wind>
        <kinematic>0</kinematic>
      </link>
      <joint name='wheel3.3_joint' type='revolute'>
        <child>wheel3.3_Link</child>
        <parent>robot_base</parent>
        <axis>
          <xyz>-7e-06 -1 4e-06</xyz>
          <limit>
            <lower>-180</lower>
            <upper>180</upper>
            <effort>0</effort>
            <velocity>0</velocity>
          </limit>
          <dynamics>
            <spring_reference>0</spring_reference>
            <spring_stiffness>0</spring_stiffness>
          </dynamics>
          <use_parent_model_frame>1</use_parent_model_frame>
        </axis>
      </joint>
      <link name='wheel3_Link'>
        <pose frame=''>-0.38871 0.295 -0.19381 1.5708 -0 3.14159</pose>
        <inertial>
          <pose frame=''>-0 0 -0.024606 0 -0 0</pose>
          <mass>0.0001</mass>
          <inertia>
            <ixx>0.00232456</ixx>
            <ixy>-1.61343e-09</ixy>
            <ixz>-4.56707e-13</ixz>
            <iyy>0.00232457</iyy>
            <iyz>-1.36036e-18</iyz>
            <izz>0.00308348</izz>
          </inertia>
        </inertial>
        <collision name='wheel3_Link_collision'>
          <pose frame=''>0 0 0 0 -0 0</pose>
          <geometry>
            <mesh>
              <scale>1 1 1</scale>
              <uri>/home/parlab/github/bunker_eplorer_ws/src/bunker_explorer_ws/ugv_gazebo_sim/bunker/bunker_description/meshes/wheel3_Link.STL</uri>
            </mesh>
          </geometry>
          <max_contacts>10</max_contacts>
          <surface>
            <contact>
              <ode/>
            </contact>
            <bounce/>
            <friction>
              <torsional>
                <ode/>
              </torsional>
              <ode/>
            </friction>
          </surface>
        </collision>
        <visual name='wheel3_Link_visual'>
          <pose frame=''>0 0 0 0 -0 0</pose>
          <geometry>
            <mesh>
              <scale>1 1 1</scale>
              <uri>/home/parlab/github/bunker_eplorer_ws/src/bunker_explorer_ws/ugv_gazebo_sim/bunker/bunker_description/meshes/wheel3_Link.STL</uri>
            </mesh>
          </geometry>
        </visual>
        <self_collide>0</self_collide>
        <enable_wind>0</enable_wind>
        <kinematic>0</kinematic>
      </link>
      <joint name='wheel3_joint' type='revolute'>
        <child>wheel3_Link</child>
        <parent>robot_base</parent>
        <axis>
          <xyz>-7e-06 -1 4e-06</xyz>
          <limit>
            <lower>-180</lower>
            <upper>180</upper>
            <effort>0</effort>
            <velocity>0</velocity>
          </limit>
          <dynamics>
            <spring_reference>0</spring_reference>
            <spring_stiffness>0</spring_stiffness>
          </dynamics>
          <use_parent_model_frame>1</use_parent_model_frame>
        </axis>
      </joint>
      <link name='wheel4.1_Link'>
        <pose frame=''>-0.23111 -0.3495 -0.27671 1.5708 -0 3.14159</pose>
        <inertial>
          <pose frame=''>-0 -0 0.072 0 -0 0</pose>
          <mass>0.0001</mass>
          <inertia>
            <ixx>0.000179574</ixx>
            <ixy>-7.93399e-21</ixy>
            <ixz>-2.13342e-21</ixz>
            <iyy>0.000179574</iyy>
            <iyz>-3.23624e-21</iyz>
            <izz>0.000332595</izz>
          </inertia>
        </inertial>
        <collision name='wheel4.1_Link_collision'>
          <pose frame=''>0 0 0 0 -0 0</pose>
          <geometry>
            <mesh>
              <scale>1 1 1</scale>
              <uri>/home/parlab/github/bunker_eplorer_ws/src/bunker_explorer_ws/ugv_gazebo_sim/bunker/bunker_description/meshes/wheel4.1_Link.STL</uri>
            </mesh>
          </geometry>
          <max_contacts>10</max_contacts>
          <surface>
            <contact>
              <ode/>
            </contact>
            <bounce/>
            <friction>
              <torsional>
                <ode/>
              </torsional>
              <ode/>
            </friction>
          </surface>
        </collision>
        <visual name='wheel4.1_Link_visual'>
          <pose frame=''>0 0 0 0 -0 0</pose>
          <geometry>
            <mesh>
              <scale>1 1 1</scale>
              <uri>/home/parlab/github/bunker_eplorer_ws/src/bunker_explorer_ws/ugv_gazebo_sim/bunker/bunker_description/meshes/wheel4.1_Link.STL</uri>
            </mesh>
          </geometry>
        </visual>
        <self_collide>0</self_collide>
        <enable_wind>0</enable_wind>
        <kinematic>0</kinematic>
      </link>
      <joint name='wheel4.1_joint' type='revolute'>
        <child>wheel4.1_Link</child>
        <parent>robot_base</parent>
        <axis>
          <xyz>-7e-06 -1 4e-06</xyz>
          <limit>
            <lower>-180</lower>
            <upper>180</upper>
            <effort>0</effort>
            <velocity>0</velocity>
          </limit>
          <dynamics>
            <spring_reference>0</spring_reference>
            <spring_stiffness>0</spring_stiffness>
          </dynamics>
          <use_parent_model_frame>1</use_parent_model_frame>
        </axis>
      </joint>
      <link name='wheel4.2_Link'>
        <pose frame=''>0.043885 -0.3495 -0.27671 1.5708 -0 3.14159</pose>
        <inertial>
          <pose frame=''>-0 -0 0.072 0 -0 0</pose>
          <mass>0.0001</mass>
          <inertia>
            <ixx>0.000179574</ixx>
            <ixy>6.30058e-22</ixy>
            <ixz>1.17534e-22</ixz>
            <iyy>0.000179574</iyy>
            <iyz>-3.27347e-21</iyz>
            <izz>0.000332595</izz>
          </inertia>
        </inertial>
        <collision name='wheel4.2_Link_collision'>
          <pose frame=''>0 0 0 0 -0 0</pose>
          <geometry>
            <mesh>
              <scale>1 1 1</scale>
              <uri>/home/parlab/github/bunker_eplorer_ws/src/bunker_explorer_ws/ugv_gazebo_sim/bunker/bunker_description/meshes/wheel4.2_Link.STL</uri>
            </mesh>
          </geometry>
          <max_contacts>10</max_contacts>
          <surface>
            <contact>
              <ode/>
            </contact>
            <bounce/>
            <friction>
              <torsional>
                <ode/>
              </torsional>
              <ode/>
            </friction>
          </surface>
        </collision>
        <visual name='wheel4.2_Link_visual'>
          <pose frame=''>0 0 0 0 -0 0</pose>
          <geometry>
            <mesh>
              <scale>1 1 1</scale>
              <uri>/home/parlab/github/bunker_eplorer_ws/src/bunker_explorer_ws/ugv_gazebo_sim/bunker/bunker_description/meshes/wheel4.2_Link.STL</uri>
            </mesh>
          </geometry>
        </visual>
        <self_collide>0</self_collide>
        <enable_wind>0</enable_wind>
        <kinematic>0</kinematic>
      </link>
      <joint name='wheel4.2_joint' type='revolute'>
        <child>wheel4.2_Link</child>
        <parent>robot_base</parent>
        <axis>
          <xyz>-7e-06 -1 4e-06</xyz>
          <limit>
            <lower>-180</lower>
            <upper>180</upper>
            <effort>0</effort>
            <velocity>0</velocity>
          </limit>
          <dynamics>
            <spring_reference>0</spring_reference>
            <spring_stiffness>0</spring_stiffness>
          </dynamics>
          <use_parent_model_frame>1</use_parent_model_frame>
        </axis>
      </joint>
      <link name='wheel4.3_Link'>
        <pose frame=''>-0.28597 -0.3495 -0.087 1.5708 -0 3.14159</pose>
        <inertial>
          <pose frame=''>0 -5.3e-05 0.070115 0 -0 0</pose>
          <mass>0.0001</mass>
          <inertia>
            <ixx>0.000105265</ixx>
            <ixy>7.98232e-12</ixy>
            <ixz>6.804e-11</ixz>
            <iyy>0.000105238</iyy>
            <iyz>-2.72106e-11</iyz>
            <izz>0.000173281</izz>
          </inertia>
        </inertial>
        <collision name='wheel4.3_Link_collision'>
          <pose frame=''>0 0 0 0 -0 0</pose>
          <geometry>
            <mesh>
              <scale>1 1 1</scale>
              <uri>/home/parlab/github/bunker_eplorer_ws/src/bunker_explorer_ws/ugv_gazebo_sim/bunker/bunker_description/meshes/wheel4.3_Link.STL</uri>
            </mesh>
          </geometry>
          <max_contacts>10</max_contacts>
          <surface>
            <contact>
              <ode/>
            </contact>
            <bounce/>
            <friction>
              <torsional>
                <ode/>
              </torsional>
              <ode/>
            </friction>
          </surface>
        </collision>
        <visual name='wheel4.3_Link_visual'>
          <pose frame=''>0 0 0 0 -0 0</pose>
          <geometry>
            <mesh>
              <scale>1 1 1</scale>
              <uri>/home/parlab/github/bunker_eplorer_ws/src/bunker_explorer_ws/ugv_gazebo_sim/bunker/bunker_description/meshes/wheel4.3_Link.STL</uri>
            </mesh>
          </geometry>
        </visual>
        <self_collide>0</self_collide>
        <enable_wind>0</enable_wind>
        <kinematic>0</kinematic>
      </link>
      <joint name='wheel4.3_joint' type='revolute'>
        <child>wheel4.3_Link</child>
        <parent>robot_base</parent>
        <axis>
          <xyz>7e-06 1 -4e-06</xyz>
          <limit>
            <lower>-180</lower>
            <upper>180</upper>
            <effort>0</effort>
            <velocity>0</velocity>
          </limit>
          <dynamics>
            <spring_reference>0</spring_reference>
            <spring_stiffness>0</spring_stiffness>
          </dynamics>
          <use_parent_model_frame>1</use_parent_model_frame>
        </axis>
      </joint>
      <link name='wheel4_Link'>
        <pose frame=''>-0.38871 -0.295 -0.19381 1.5708 -0 3.14159</pose>
        <inertial>
          <pose frame=''>0 0 0.024593 0 -0 0</pose>
          <mass>0.0001</mass>
          <inertia>
            <ixx>0.00232457</ixx>
            <ixy>-1.61343e-09</ixy>
            <ixz>-3.67392e-19</ixz>
            <iyy>0.00232456</iyy>
            <iyz>-4.56707e-13</iyz>
            <izz>0.00308348</izz>
          </inertia>
        </inertial>
        <collision name='wheel4_Link_collision'>
          <pose frame=''>0 0 0 0 -0 0</pose>
          <geometry>
            <mesh>
              <scale>1 1 1</scale>
              <uri>/home/parlab/github/bunker_eplorer_ws/src/bunker_explorer_ws/ugv_gazebo_sim/bunker/bunker_description/meshes/wheel4_Link.STL</uri>
            </mesh>
          </geometry>
          <max_contacts>10</max_contacts>
          <surface>
            <contact>
              <ode/>
            </contact>
            <bounce/>
            <friction>
              <torsional>
                <ode/>
              </torsional>
              <ode/>
            </friction>
          </surface>
        </collision>
        <visual name='wheel4_Link_visual'>
          <pose frame=''>0 0 0 0 -0 0</pose>
          <geometry>
            <mesh>
              <scale>1 1 1</scale>
              <uri>/home/parlab/github/bunker_eplorer_ws/src/bunker_explorer_ws/ugv_gazebo_sim/bunker/bunker_description/meshes/wheel4_Link.STL</uri>
            </mesh>
          </geometry>
        </visual>
        <self_collide>0</self_collide>
        <enable_wind>0</enable_wind>
        <kinematic>0</kinematic>
      </link>
      <joint name='wheel4_joint' type='revolute'>
        <child>wheel4_Link</child>
        <parent>robot_base</parent>
        <axis>
          <xyz>7e-06 1 -4e-06</xyz>
          <limit>
            <lower>-180</lower>
            <upper>180</upper>
            <effort>0</effort>
            <velocity>0</velocity>
          </limit>
          <dynamics>
            <spring_reference>0</spring_reference>
            <spring_stiffness>0</spring_stiffness>
          </dynamics>
          <use_parent_model_frame>1</use_parent_model_frame>
        </axis>
      </joint>
      <plugin name='object_controller' filename='libgazebo_ros_planar_move.so'>
        <commandTopic>smoother_cmd_vel</commandTopic>
        <odometryTopic>odom</odometryTopic>
        <odometryFrame>odom</odometryFrame>
        <odometryRate>20.0</odometryRate>
        <leftFrontJoint>wheel1_2_joint</leftFrontJoint>
        <rightFrontJoint>wheel2_2_joint</rightFrontJoint>
        <leftRearJoint>wheel3_1_joint</leftRearJoint>
        <rightRearJoint>wheel4_1_joint</rightRearJoint>
        <robotBaseFrame>robot_base</robotBaseFrame>
        <robotNamespace>/</robotNamespace>
      </plugin>
      <plugin name='gazebo_ros_control' filename='libgazebo_ros_control.so'>
        <robotSimType>gazebo_ros_control/DefaultRobotHWSim</robotSimType>
        <legacyModeNS>1</legacyModeNS>
        <robotNamespace>/</robotNamespace>
      </plugin>
      <plugin name='gps_controller' filename='libhector_gazebo_ros_gps.so'>
        <updateRate>40</updateRate>
        <frameId>gps_link</frameId>
        <topicName>ublox_gps/fix</topicName>
        <velocityTopicName>ublox_gps/vel</velocityTopicName>
        <referenceLatitude>37.871112</referenceLatitude>
        <referenceLongitude>127.746019</referenceLongitude>
        <referenceHeading>0</referenceHeading>
        <referenceAltitude>0</referenceAltitude>
        <drift>0.001 0.001 0.001</drift>
        <robotNamespace>/</robotNamespace>
        <bodyName>robot_base</bodyName>
        <xyzOffset>0.25 0 -0.29</xyzOffset>
        <rpyOffset>0 -0 0</rpyOffset>
      </plugin>
      <static>0</static>
      <plugin name='imu_controller' filename='libhector_gazebo_ros_imu.so'>
        <robotNamespace>/</robotNamespace>
        <updateRate>50.0</updateRate>
        <topicName>imu/data</topicName>
        <accelDrift>0.005 0.005 0.005</accelDrift>
        <accelGaussianNoise>0.005 0.005 0.005</accelGaussianNoise>
        <rateDrift>0.005 0.005 0.005</rateDrift>
        <rateGaussianNoise>0.005 0.005 0.005</rateGaussianNoise>
        <headingDrift>0.005</headingDrift>
        <headingGaussianNoise>0.005</headingGaussianNoise>
        <bodyName>robot_base</bodyName>
        <xyzOffset>-0.33 0.065 -0.29</xyzOffset>
        <rpyOffset>0 -0 0</rpyOffset>
      </plugin>
      <pose frame=''>0 0 0 0 -0 0</pose>
    </model>
    <model name='Tree 2 0.7_0'>
      <static>1</static>
      <pose frame=''>3.99409 1.00156 0 1.57079 -0 0</pose>
      <link name='link'>
        <pose frame=''>0 0 0 0 -0 0</pose>
        <collision name='collision'>
          <geometry>
            <mesh>
              <scale>0.7 0.7 0.7</scale>
              <uri>model://tree_2/meshes/tree_2.obj</uri>
            </mesh>
          </geometry>
          <max_contacts>10</max_contacts>
          <surface>
            <contact>
              <ode/>
            </contact>
            <bounce/>
            <friction>
              <torsional>
                <ode/>
              </torsional>
              <ode/>
            </friction>
          </surface>
        </collision>
        <visual name='visual'>
          <geometry>
            <mesh>
              <scale>0.7 0.7 0.7</scale>
              <uri>model://tree_2/meshes/tree_2.obj</uri>
            </mesh>
          </geometry>
        </visual>
        <self_collide>0</self_collide>
        <enable_wind>0</enable_wind>
        <kinematic>0</kinematic>
      </link>
    </model>
    <model name='Tree 2 0.7_1'>
      <static>1</static>
      <pose frame=''>6.02264 1.00606 0 1.57079 -0 0</pose>
      <link name='link'>
        <pose frame=''>0 0 0 0 -0 0</pose>
        <collision name='collision'>
          <geometry>
            <mesh>
              <scale>0.7 0.7 0.7</scale>
              <uri>model://tree_2/meshes/tree_2.obj</uri>
            </mesh>
          </geometry>
          <max_contacts>10</max_contacts>
          <surface>
            <contact>
              <ode/>
            </contact>
            <bounce/>
            <friction>
              <torsional>
                <ode/>
              </torsional>
              <ode/>
            </friction>
          </surface>
        </collision>
        <visual name='visual'>
          <geometry>
            <mesh>
              <scale>0.7 0.7 0.7</scale>
              <uri>model://tree_2/meshes/tree_2.obj</uri>
            </mesh>
          </geometry>
        </visual>
        <self_collide>0</self_collide>
        <enable_wind>0</enable_wind>
        <kinematic>0</kinematic>
      </link>
    </model>
    <model name='Tree 2 0.7_2'>
      <static>1</static>
      <pose frame=''>6.12509 4.02684 0 1.57079 -0 0</pose>
      <link name='link'>
        <pose frame=''>0 0 0 0 -0 0</pose>
        <collision name='collision'>
          <geometry>
            <mesh>
              <scale>0.7 0.7 0.7</scale>
              <uri>model://tree_2/meshes/tree_2.obj</uri>
            </mesh>
          </geometry>
          <max_contacts>10</max_contacts>
          <surface>
            <contact>
              <ode/>
            </contact>
            <bounce/>
            <friction>
              <torsional>
                <ode/>
              </torsional>
              <ode/>
            </friction>
          </surface>
        </collision>
        <visual name='visual'>
          <geometry>
            <mesh>
              <scale>0.7 0.7 0.7</scale>
              <uri>model://tree_2/meshes/tree_2.obj</uri>
            </mesh>
          </geometry>
        </visual>
        <self_collide>0</self_collide>
        <enable_wind>0</enable_wind>
        <kinematic>0</kinematic>
      </link>
    </model>
    <model name='Tree 2 0.7'>
      <static>1</static>
      <pose frame=''>1.9918 1.00407 0 1.57079 -0 0</pose>
      <link name='link'>
        <pose frame=''>0 0 0 0 -0 0</pose>
        <collision name='collision'>
          <geometry>
            <mesh>
              <scale>0.7 0.7 0.7</scale>
              <uri>model://tree_2/meshes/tree_2.obj</uri>
            </mesh>
          </geometry>
          <max_contacts>10</max_contacts>
          <surface>
            <contact>
              <ode/>
            </contact>
            <bounce/>
            <friction>
              <torsional>
                <ode/>
              </torsional>
              <ode/>
            </friction>
          </surface>
        </collision>
        <visual name='visual'>
          <geometry>
            <mesh>
              <scale>0.7 0.7 0.7</scale>
              <uri>model://tree_2/meshes/tree_2.obj</uri>
            </mesh>
          </geometry>
        </visual>
        <self_collide>0</self_collide>
        <enable_wind>0</enable_wind>
        <kinematic>0</kinematic>
      </link>
    </model>
    <model name='Tree 2 0.7_3'>
      <static>1</static>
      <pose frame=''>3.99827 4.00619 0 1.57079 -0 0</pose>
      <link name='link'>
        <pose frame=''>0 0 0 0 -0 0</pose>
        <collision name='collision'>
          <geometry>
            <mesh>
              <scale>0.7 0.7 0.7</scale>
              <uri>model://tree_2/meshes/tree_2.obj</uri>
            </mesh>
          </geometry>
          <max_contacts>10</max_contacts>
          <surface>
            <contact>
              <ode/>
            </contact>
            <bounce/>
            <friction>
              <torsional>
                <ode/>
              </torsional>
              <ode/>
            </friction>
          </surface>
        </collision>
        <visual name='visual'>
          <geometry>
            <mesh>
              <scale>0.7 0.7 0.7</scale>
              <uri>model://tree_2/meshes/tree_2.obj</uri>
            </mesh>
          </geometry>
        </visual>
        <self_collide>0</self_collide>
        <enable_wind>0</enable_wind>
        <kinematic>0</kinematic>
      </link>
    </model>
    <model name='Tree 2 0.7_4'>
      <static>1</static>
      <pose frame=''>1.98994 3.99531 0 1.57079 -0 0</pose>
      <link name='link'>
        <pose frame=''>0 0 0 0 -0 0</pose>
        <collision name='collision'>
          <geometry>
            <mesh>
              <scale>0.7 0.7 0.7</scale>
              <uri>model://tree_2/meshes/tree_2.obj</uri>
            </mesh>
          </geometry>
          <max_contacts>10</max_contacts>
          <surface>
            <contact>
              <ode/>
            </contact>
            <bounce/>
            <friction>
              <torsional>
                <ode/>
              </torsional>
              <ode/>
            </friction>
          </surface>
        </collision>
        <visual name='visual'>
          <geometry>
            <mesh>
              <scale>0.7 0.7 0.7</scale>
              <uri>model://tree_2/meshes/tree_2.obj</uri>
            </mesh>
          </geometry>
        </visual>
        <self_collide>0</self_collide>
        <enable_wind>0</enable_wind>
        <kinematic>0</kinematic>
      </link>
    </model>
    <model name='Tree 2 0.7_5'>
      <static>1</static>
      <pose frame=''>1.96741 6.99255 0 1.57079 -0 0</pose>
      <link name='link'>
        <pose frame=''>0 0 0 0 -0 0</pose>
        <collision name='collision'>
          <geometry>
            <mesh>
              <scale>0.7 0.7 0.7</scale>
              <uri>model://tree_2/meshes/tree_2.obj</uri>
            </mesh>
          </geometry>
          <max_contacts>10</max_contacts>
          <surface>
            <contact>
              <ode/>
            </contact>
            <bounce/>
            <friction>
              <torsional>
                <ode/>
              </torsional>
              <ode/>
            </friction>
          </surface>
        </collision>
        <visual name='visual'>
          <geometry>
            <mesh>
              <scale>0.7 0.7 0.7</scale>
              <uri>model://tree_2/meshes/tree_2.obj</uri>
            </mesh>
          </geometry>
        </visual>
        <self_collide>0</self_collide>
        <enable_wind>0</enable_wind>
        <kinematic>0</kinematic>
      </link>
    </model>
    <model name='Tree 2 0.7_6'>
      <static>1</static>
      <pose frame=''>4.00021 7.00847 0 1.57079 -0 0</pose>
      <link name='link'>
        <pose frame=''>0 0 0 0 -0 0</pose>
        <collision name='collision'>
          <geometry>
            <mesh>
              <scale>0.7 0.7 0.7</scale>
              <uri>model://tree_2/meshes/tree_2.obj</uri>
            </mesh>
          </geometry>
          <max_contacts>10</max_contacts>
          <surface>
            <contact>
              <ode/>
            </contact>
            <bounce/>
            <friction>
              <torsional>
                <ode/>
              </torsional>
              <ode/>
            </friction>
          </surface>
        </collision>
        <visual name='visual'>
          <geometry>
            <mesh>
              <scale>0.7 0.7 0.7</scale>
              <uri>model://tree_2/meshes/tree_2.obj</uri>
            </mesh>
          </geometry>
        </visual>
        <self_collide>0</self_collide>
        <enable_wind>0</enable_wind>
        <kinematic>0</kinematic>
      </link>
    </model>
    <model name='Tree 2 0.7_7'>
      <static>1</static>
      <pose frame=''>6.00405 7.00328 0 1.57079 -0 0</pose>
      <link name='link'>
        <pose frame=''>0 0 0 0 -0 0</pose>
        <collision name='collision'>
          <geometry>
            <mesh>
              <scale>0.7 0.7 0.7</scale>
              <uri>model://tree_2/meshes/tree_2.obj</uri>
            </mesh>
          </geometry>
          <max_contacts>10</max_contacts>
          <surface>
            <contact>
              <ode/>
            </contact>
            <bounce/>
            <friction>
              <torsional>
                <ode/>
              </torsional>
              <ode/>
            </friction>
          </surface>
        </collision>
        <visual name='visual'>
          <geometry>
            <mesh>
              <scale>0.7 0.7 0.7</scale>
              <uri>model://tree_2/meshes/tree_2.obj</uri>
            </mesh>
          </geometry>
        </visual>
        <self_collide>0</self_collide>
        <enable_wind>0</enable_wind>
        <kinematic>0</kinematic>
      </link>
    </model>
    <state world_name='default'>
      <sim_time>1161 935000000</sim_time>
      <real_time>8494 917660664</real_time>
      <wall_time>1702015577 8619736</wall_time>
      <iterations>1161935</iterations>
      <model name='Tree 2 0.7'>
        <pose frame=''>1.9918 1.00407 0 1.57079 -0 0</pose>
        <scale>1 1 1</scale>
        <link name='link'>
          <pose frame=''>1.9918 1.00407 0 1.57079 -0 0</pose>
          <velocity>0 0 0 0 -0 0</velocity>
          <acceleration>0 0 0 0 -0 0</acceleration>
          <wrench>0 0 0 0 -0 0</wrench>
        </link>
      </model>
      <model name='Tree 2 0.7_0'>
        <pose frame=''>3.99409 1.00156 0 1.57079 -0 0</pose>
        <scale>1 1 1</scale>
        <link name='link'>
          <pose frame=''>3.99409 1.00156 0 1.57079 -0 0</pose>
          <velocity>0 0 0 0 -0 0</velocity>
          <acceleration>0 0 0 0 -0 0</acceleration>
          <wrench>0 0 0 0 -0 0</wrench>
        </link>
      </model>
      <model name='Tree 2 0.7_1'>
        <pose frame=''>6.02264 1.00606 0 1.57079 -0 0</pose>
        <scale>1 1 1</scale>
        <link name='link'>
          <pose frame=''>6.02264 1.00606 0 1.57079 -0 0</pose>
          <velocity>0 0 0 0 -0 0</velocity>
          <acceleration>0 0 0 0 -0 0</acceleration>
          <wrench>0 0 0 0 -0 0</wrench>
        </link>
      </model>
      <model name='Tree 2 0.7_2'>
        <pose frame=''>6.12509 4.02684 0 1.57079 -0 0</pose>
        <scale>1 1 1</scale>
        <link name='link'>
          <pose frame=''>6.12509 4.02684 0 1.57079 -0 0</pose>
          <velocity>0 0 0 0 -0 0</velocity>
          <acceleration>0 0 0 0 -0 0</acceleration>
          <wrench>0 0 0 0 -0 0</wrench>
        </link>
      </model>
      <model name='Tree 2 0.7_3'>
        <pose frame=''>3.99827 4.00619 0 1.57079 -0 0</pose>
        <scale>1 1 1</scale>
        <link name='link'>
          <pose frame=''>3.99827 4.00619 0 1.57079 -0 0</pose>
          <velocity>0 0 0 0 -0 0</velocity>
          <acceleration>0 0 0 0 -0 0</acceleration>
          <wrench>0 0 0 0 -0 0</wrench>
        </link>
      </model>
      <model name='Tree 2 0.7_4'>
        <pose frame=''>1.98994 3.99531 0 1.57079 -0 0</pose>
        <scale>1 1 1</scale>
        <link name='link'>
          <pose frame=''>1.98994 3.99531 0 1.57079 -0 0</pose>
          <velocity>0 0 0 0 -0 0</velocity>
          <acceleration>0 0 0 0 -0 0</acceleration>
          <wrench>0 0 0 0 -0 0</wrench>
        </link>
      </model>
      <model name='Tree 2 0.7_5'>
        <pose frame=''>1.96741 6.99255 0 1.57079 -0 0</pose>
        <scale>1 1 1</scale>
        <link name='link'>
          <pose frame=''>1.96741 6.99255 0 1.57079 -0 0</pose>
          <velocity>0 0 0 0 -0 0</velocity>
          <acceleration>0 0 0 0 -0 0</acceleration>
          <wrench>0 0 0 0 -0 0</wrench>
        </link>
      </model>
      <model name='Tree 2 0.7_6'>
        <pose frame=''>4.00021 7.00847 0 1.57079 -0 0</pose>
        <scale>1 1 1</scale>
        <link name='link'>
          <pose frame=''>4.00021 7.00847 0 1.57079 -0 0</pose>
          <velocity>0 0 0 0 -0 0</velocity>
          <acceleration>0 0 0 0 -0 0</acceleration>
          <wrench>0 0 0 0 -0 0</wrench>
        </link>
      </model>
      <model name='Tree 2 0.7_7'>
        <pose frame=''>6.00405 7.00328 0 1.57079 -0 0</pose>
        <scale>1 1 1</scale>
        <link name='link'>
          <pose frame=''>6.00405 7.00328 0 1.57079 -0 0</pose>
          <velocity>0 0 0 0 -0 0</velocity>
          <acceleration>0 0 0 0 -0 0</acceleration>
          <wrench>0 0 0 0 -0 0</wrench>
        </link>
      </model>
      <model name='bunker'>
        <pose frame=''>1.49365 2.51991 0.357107 -0.000807 -0.002168 0.008632</pose>
        <scale>1 1 1</scale>
        <link name='robot_base'>
          <pose frame=''>1.49365 2.51991 0.357107 -0.000807 -0.002168 0.008632</pose>
          <velocity>0 0 -0.01011 0 -0 0</velocity>
          <acceleration>4.2e-05 0.000405 -10.1105 8e-06 -4.3e-05 -0</acceleration>
          <wrench>0 0 -0.001011 0 -0 0</wrench>
        </link>
        <link name='wheel1.1_Link'>
          <pose frame=''>1.86661 2.87246 0.13459 1.57161 -3e-06 -3.13296</pose>
          <velocity>-0 -0 -0.010145 1e-06 -0 0</velocity>
          <acceleration>-1e-05 -0.000193 -10.1449 0.001277 1.1e-05 7e-06</acceleration>
          <wrench>-0 -0 -0.001014 0 -0 0</wrench>
        </link>
        <link name='wheel1.2_Link'>
          <pose frame=''>1.78162 2.87168 0.076416 1.57161 0.000251 -3.13296</pose>
          <velocity>-0 -0 -0.010177 0 -0 0</velocity>
          <acceleration>-7e-06 -0.000177 -10.1767 0.000116 1e-06 7e-06</acceleration>
          <wrench>-0 -0 -0.001018 0 -0 0</wrench>
        </link>
        <link name='wheel1.3_Link'>
          <pose frame=''>1.78684 2.87188 0.270467 1.57161 0.000229 -3.13296</pose>
          <velocity>-0 -0 -0.010158 -1e-06 0 0</velocity>
          <acceleration>-1.5e-05 -0.000203 -10.1582 -0.000696 -2e-06 6e-06</acceleration>
          <wrench>-0 -0 -0.001016 0 -0 0</wrench>
        </link>
        <link name='wheel1_Link'>
          <pose frame=''>1.93492 2.87312 0.229259 1.57161 -1e-06 -3.13296</pose>
          <velocity>-0 -0 -0.010091 0 -0 0</velocity>
          <acceleration>-1.3e-05 -0.000151 -10.0911 -0.000254 -2e-06 7e-06</acceleration>
          <wrench>-0 -0 -0.001009 0 -0 0</wrench>
        </link>
        <link name='wheel2.1_Link'>
          <pose frame=''>1.87264 2.17348 0.135155 1.57161 3e-06 -3.13296</pose>
          <velocity>-0 -0 -0.009985 3e-06 -0 0</velocity>
          <acceleration>-8e-06 -0.000101 -9.98497 0.003457 3e-05 7e-06</acceleration>
          <wrench>-0 -0 -0.000998 0 -0 0</wrench>
        </link>
        <link name='wheel2.2_Link'>
          <pose frame=''>1.78765 2.17271 0.076981 1.57161 0.000152 -3.13296</pose>
          <velocity>-0 -0 -0.009852 1e-06 -0 0</velocity>
          <acceleration>-9e-06 -7.6e-05 -9.85218 0.001497 1.3e-05 7e-06</acceleration>
          <wrench>-0 -0 -0.000985 0 -0 0</wrench>
        </link>
        <link name='wheel2.3_Link'>
          <pose frame=''>1.79287 2.17291 0.271034 1.57161 0.00024 -3.13296</pose>
          <velocity>-0 -0 -0.009712 2e-06 -0 0</velocity>
          <acceleration>-2.1e-05 -9.3e-05 -9.71184 0.002285 1.9e-05 6e-06</acceleration>
          <wrench>-0 -0 -0.000971 0 -0 0</wrench>
        </link>
        <link name='wheel2_Link'>
          <pose frame=''>1.94096 2.17415 0.229825 1.57161 1e-06 -3.13296</pose>
          <velocity>-0 -0 -0.009582 1e-06 -0 0</velocity>
          <acceleration>-1.9e-05 -3.8e-05 -9.58209 0.000654 6e-06 7e-06</acceleration>
          <wrench>-0 -0 -0.000958 0 -0 0</wrench>
        </link>
        <link name='wheel3.1_Link'>
          <pose frame=''>1.26013 2.86718 0.079618 1.57161 -7.6e-05 -3.13296</pose>
          <velocity>-0 0 -0.009481 0 -0 0</velocity>
          <acceleration>-1.1e-05 1.8e-05 -9.48129 -0.000481 -4e-06 7e-06</acceleration>
          <wrench>-0 0 -0.000948 0 -0 0</wrench>
        </link>
        <link name='wheel3.2_Link'>
          <pose frame=''>1.53512 2.86955 0.080215 1.57161 -9.4e-05 -3.13296</pose>
          <velocity>-0 0 -0.009423 0 -0 0</velocity>
          <acceleration>-7e-06 2.8e-05 -9.423 -1.4e-05 -0 7e-06</acceleration>
          <wrench>-0 0 -0.000942 0 -0 0</wrench>
        </link>
        <link name='wheel3.3_Link'>
          <pose frame=''>1.20486 2.86686 0.269209 1.57161 -0 -3.13296</pose>
          <velocity>-0 0 -0.009415 1e-06 -0 0</velocity>
          <acceleration>-1e-05 1.2e-05 -9.41543 0.000682 6e-06 6e-06</acceleration>
          <wrench>-0 0 -0.000942 0 -0 0</wrench>
        </link>
        <link name='wheel3_Link'>
          <pose frame=''>1.10283 2.81139 0.16222 1.57161 -0 -3.13296</pose>
          <velocity>0 0 -0.00946 0 -0 0</velocity>
          <acceleration>4e-06 7.4e-05 -9.46021 0.000187 2e-06 5e-06</acceleration>
          <wrench>0 0 -0.000946 0 -0 0</wrench>
        </link>
        <link name='wheel4.1_Link'>
          <pose frame=''>1.26617 2.16821 0.080182 1.57161 -0.0001 -3.13296</pose>
          <velocity>0 0 -0.009551 -1e-06 -0 0</velocity>
          <acceleration>1.8e-05 0.00011 -9.5512 -0.00095 -8e-06 6e-06</acceleration>
          <wrench>0 0 -0.000955 0 -0 0</wrench>
        </link>
        <link name='wheel4.2_Link'>
          <pose frame=''>1.54115 2.17058 0.080778 1.57161 -0.001463 -3.13297</pose>
          <velocity>0 0 -0.009676 -1e-06 -0 0</velocity>
          <acceleration>2.3e-05 0.000118 -9.67649 -0.001148 -1e-05 7e-06</acceleration>
          <wrench>0 0 -0.000968 0 -0 0</wrench>
        </link>
        <link name='wheel4.3_Link'>
          <pose frame=''>1.2109 2.16788 0.269771 1.57161 4e-06 -3.13296</pose>
          <velocity>0 0 -0.009819 -2e-06 -0 0</velocity>
          <acceleration>1.7e-05 0.0001 -9.81925 -0.002054 -1.8e-05 6e-06</acceleration>
          <wrench>0 0 -0.000982 0 -0 0</wrench>
        </link>
        <link name='wheel4_Link'>
          <pose frame=''>1.10792 2.22141 0.162694 1.57161 -0 -3.13296</pose>
          <velocity>0 0 -0.009961 0 -0 0</velocity>
          <acceleration>2.7e-05 0.000166 -9.96066 0.00015 1e-06 5e-06</acceleration>
          <wrench>0 0 -0.000996 0 -0 0</wrench>
        </link>
      </model>
      <model name='ground_plane'>
        <pose frame=''>0 0 0 0 -0 0</pose>
        <scale>1 1 1</scale>
        <link name='link'>
          <pose frame=''>0 0 0 0 -0 0</pose>
          <velocity>0 0 0 0 -0 0</velocity>
          <acceleration>0 0 0 0 -0 0</acceleration>
          <wrench>0 0 0 0 -0 0</wrench>
        </link>
      </model>
      <light name='sun'>
        <pose frame=''>0 0 10 0 -0 0</pose>
      </light>
    </state>
    <gui fullscreen='0'>
      <camera name='user_camera'>
        <pose frame=''>-4.3791 -1.41771 8.88109 0 0.694202 0.562451</pose>
        <view_controller>orbit</view_controller>
        <projection_type>perspective</projection_type>
      </camera>
    </gui>
  </world>
</sdf>
