<?xml version="1.0" ?>
<sdf version='1.6'>
  <world name='default'>
    <light name='sun' type='directional'>
      <cast_shadows>1</cast_shadows>
      <pose frame=''>0 0 10 0 -0 0</pose>
      <diffuse>0.8 0.8 0.8 1</diffuse>
      <specular>0.2 0.2 0.2 1</specular>
      <attenuation>
        <range>1000</range>
        <constant>0.9</constant>
        <linear>0.01</linear>
        <quadratic>0.001</quadratic>
      </attenuation>
      <direction>-0.5 0.1 -0.9</direction>
    </light>
    <model name='ground_plane'>
      <static>1</static>
      <link name='link'>
        <collision name='collision'>
          <geometry>
            <plane>
              <normal>0 0 1</normal>
              <size>100 100</size>
            </plane>
          </geometry>
          <surface>
            <contact>
              <collide_bitmask>65535</collide_bitmask>
              <ode/>
            </contact>
            <friction>
              <ode>
                <mu>100</mu>
                <mu2>50</mu2>
              </ode>
              <torsional>
                <ode/>
              </torsional>
            </friction>
            <bounce/>
          </surface>
          <max_contacts>10</max_contacts>
        </collision>
        <visual name='visual'>
          <cast_shadows>0</cast_shadows>
          <geometry>
            <plane>
              <normal>0 0 1</normal>
              <size>100 100</size>
            </plane>
          </geometry>
          <material>
            <script>
              <uri>file://media/materials/scripts/gazebo.material</uri>
              <name>Gazebo/Grey</name>
            </script>
          </material>
        </visual>
        <self_collide>0</self_collide>
        <enable_wind>0</enable_wind>
        <kinematic>0</kinematic>
      </link>
    </model>
    <gravity>0 0 -9.8</gravity>
    <magnetic_field>6e-06 2.3e-05 -4.2e-05</magnetic_field>
    <atmosphere type='adiabatic'/>
    <physics name='default_physics' default='0' type='ode'>
      <max_step_size>0.001</max_step_size>
      <real_time_factor>1</real_time_factor>
      <real_time_update_rate>1000</real_time_update_rate>
    </physics>
    <scene>
      <ambient>0.4 0.4 0.4 1</ambient>
      <background>0.7 0.7 0.7 1</background>
      <shadows>1</shadows>
    </scene>
    <audio>
      <device>default</device>
    </audio>
    <wind/>
    <spherical_coordinates>
      <surface_model>EARTH_WGS84</surface_model>
      <latitude_deg>0</latitude_deg>
      <longitude_deg>0</longitude_deg>
      <elevation>0</elevation>
      <heading_deg>0</heading_deg>
    </spherical_coordinates>
    <model name='bunker'>
      <link name='robot_base'>
        <pose frame=''>0 0 0 0 -0 0</pose>
        <inertial>
          <pose frame=''>0.021241 0.004755 -0.127581 0 -0 0</pose>
          <mass>0.0001</mass>
          <inertia>
            <ixx>0.607716</ixx>
            <ixy>1.92178e-05</ixy>
            <ixz>-0.0365321</ixz>
            <iyy>1.70041</iyy>
            <iyz>2.16963e-05</iyz>
            <izz>1.84232</izz>
          </inertia>
        </inertial>
        <collision name='robot_base_collision'>
          <pose frame=''>0.53 -0.392 -0.358 1.57 0 3.14</pose>
          <geometry>
            <mesh>
              <scale>0.001 0.001 0.001</scale>
              <uri>/home/andi/catkin_redevel_ws/src/ugv_gazebo_sim/bunker/bunker_description/meshes/BUNKER.STL</uri>
            </mesh>
          </geometry>
          <surface>
            <contact>
              <ode/>
            </contact>
            <friction>
              <ode/>
              <torsional>
                <ode/>
              </torsional>
            </friction>
            <bounce/>
          </surface>
          <max_contacts>10</max_contacts>
        </collision>
        <collision name='robot_base_fixed_joint_lump__camera_link_collision_1'>
          <pose frame=''>0.333 0 0.297 0 -0 0</pose>
          <geometry>
            <box>
              <size>0.012 0.132 0.02</size>
            </box>
          </geometry>
          <max_contacts>10</max_contacts>
          <surface>
            <contact>
              <ode/>
            </contact>
            <bounce/>
            <friction>
              <torsional>
                <ode/>
              </torsional>
              <ode/>
            </friction>
          </surface>
        </collision>
        <visual name='robot_base_visual'>
          <pose frame=''>0.53 -0.392 -0.358 1.57 0 3.14</pose>
          <geometry>
            <mesh>
              <scale>0.001 0.001 0.001</scale>
              <uri>/home/andi/catkin_redevel_ws/src/ugv_gazebo_sim/bunker/bunker_description/meshes/BUNKER.STL</uri>
            </mesh>
          </geometry>
          <material>
            <script>
              <name>Gazebo/Gray</name>
              <uri>file://media/materials/scripts/gazebo.material</uri>
            </script>
          </material>
        </visual>
        <visual name='robot_base_fixed_joint_lump__rbot_base2_visual_1'>
          <pose frame=''>0.3 0 0 0 -0 0</pose>
          <geometry>
            <box>
              <size>0.045 0.09 0.03</size>
            </box>
          </geometry>
        </visual>
        <visual name='robot_base_fixed_joint_lump__servo_bottom2_visual_2'>
          <pose frame=''>0.3 0 0.14 0 -0 0</pose>
          <geometry>
            <cylinder>
              <length>0.25</length>
              <radius>0.015</radius>
            </cylinder>
          </geometry>
        </visual>
        <visual name='robot_base_fixed_joint_lump__up_mount2_visual_3'>
          <pose frame=''>0.3 0 0.29 0 -0 0</pose>
          <geometry>
            <box>
              <size>0.05 0.148 0.05</size>
            </box>
          </geometry>
        </visual>
        <visual name='robot_base_fixed_joint_lump__camera_link_visual_4'>
          <pose frame=''>0.33 -0.065 0.29 1.57 -0 1.57</pose>
          <geometry>
            <mesh>
              <scale>1 1 1</scale>
              <uri>/home/andi/catkin_redevel_ws/src/ugv_gazebo_sim/bunker/bunker_description/meshes/sensors/r200.dae</uri>
            </mesh>
          </geometry>
        </visual>
        <velocity_decay/>
        <gravity>1</gravity>
        <velocity_decay/>
        <sensor name='realsense_R200' type='depth'>
          <always_on>1</always_on>
          <visualize>0</visualize>
          <camera name='__default__'>
            <horizontal_fov>1.3439</horizontal_fov>
            <image>
              <width>1920</width>
              <height>1080</height>
              <format>R8G8B8</format>
            </image>
            <depth_camera>
              <output>depths</output>
            </depth_camera>
            <clip>
              <near>0.03</near>
              <far>100</far>
            </clip>
          </camera>
          <plugin name='camera_controller' filename='libgazebo_ros_openni_kinect.so'>
            <baseline>0.2</baseline>
            <alwaysOn>1</alwaysOn>
            <updateRate>30.0</updateRate>
            <cameraName>camera</cameraName>
            <frameName>camera_rgb_optical_frame</frameName>
            <imageTopicName>rgb/image_raw</imageTopicName>
            <depthImageTopicName>depth/image_raw</depthImageTopicName>
            <pointCloudTopicName>depth/points</pointCloudTopicName>
            <cameraInfoTopicName>rgb/camera_info</cameraInfoTopicName>
            <depthImageCameraInfoTopicName>depth/camera_info</depthImageCameraInfoTopicName>
            <pointCloudCutoff>0.4</pointCloudCutoff>
            <hackBaseline>0.07</hackBaseline>
            <distortionK1>0.0</distortionK1>
            <distortionK2>0.0</distortionK2>
            <distortionK3>0.0</distortionK3>
            <distortionT1>0.0</distortionT1>
            <distortionT2>0.0</distortionT2>
            <CxPrime>0.0</CxPrime>
            <Cx>0.0</Cx>
            <Cy>0.0</Cy>
            <focalLength>0</focalLength>
            <hackBaseline>0</hackBaseline>
            <robotNamespace>/</robotNamespace>
          </plugin>
          <pose frame=''>0.335 -0.047 0.303 0 -0 0</pose>
        </sensor>
        <self_collide>0</self_collide>
        <enable_wind>0</enable_wind>
        <kinematic>0</kinematic>
      </link>
      <link name='wheel1.1_Link'>
        <pose frame=''>0.37551 0.3495 -0.22305 1.5708 -0 3.14159</pose>
        <inertial>
          <pose frame=''>-0 0 -0.072 0 -0 0</pose>
          <mass>0.0001</mass>
          <inertia>
            <ixx>6.58751e-05</ixx>
            <ixy>-1.46559e-09</ixy>
            <ixz>-8.34967e-12</ixz>
            <iyy>6.58796e-05</iyy>
            <iyz>-2.4786e-12</iyz>
            <izz>0.000112722</izz>
          </inertia>
        </inertial>
        <collision name='wheel1.1_Link_collision'>
          <pose frame=''>0 0 0 0 -0 0</pose>
          <geometry>
            <mesh>
              <scale>1 1 1</scale>
              <uri>/home/andi/catkin_redevel_ws/src/ugv_gazebo_sim/bunker/bunker_description/meshes/wheel1.1_Link.STL</uri>
            </mesh>
          </geometry>
          <max_contacts>10</max_contacts>
          <surface>
            <contact>
              <ode/>
            </contact>
            <bounce/>
            <friction>
              <torsional>
                <ode/>
              </torsional>
              <ode/>
            </friction>
          </surface>
        </collision>
        <visual name='wheel1.1_Link_visual'>
          <pose frame=''>0 0 0 0 -0 0</pose>
          <geometry>
            <mesh>
              <scale>1 1 1</scale>
              <uri>/home/andi/catkin_redevel_ws/src/ugv_gazebo_sim/bunker/bunker_description/meshes/wheel1.1_Link.STL</uri>
            </mesh>
          </geometry>
        </visual>
        <self_collide>0</self_collide>
        <enable_wind>0</enable_wind>
        <kinematic>0</kinematic>
      </link>
      <joint name='wheel1.1_jont' type='revolute'>
        <child>wheel1.1_Link</child>
        <parent>robot_base</parent>
        <axis>
          <xyz>7e-06 1 -4e-06</xyz>
          <limit>
            <lower>-180</lower>
            <upper>180</upper>
            <effort>0</effort>
            <velocity>0</velocity>
          </limit>
          <dynamics>
            <spring_reference>0</spring_reference>
            <spring_stiffness>0</spring_stiffness>
          </dynamics>
          <use_parent_model_frame>1</use_parent_model_frame>
        </axis>
      </joint>
      <link name='wheel1.2_Link'>
        <pose frame=''>0.29039 0.3495 -0.28104 1.5708 -0 3.14159</pose>
        <inertial>
          <pose frame=''>0 0 -0.072 0 -0 0</pose>
          <mass>0.0001</mass>
          <inertia>
            <ixx>0.000179574</ixx>
            <ixy>1.15789e-20</ixy>
            <ixz>1.35634e-21</ixz>
            <iyy>0.000179574</iyy>
            <iyz>6.03698e-23</iyz>
            <izz>0.000332595</izz>
          </inertia>
        </inertial>
        <collision name='wheel1.2_Link_collision'>
          <pose frame=''>0 0 0 0 -0 0</pose>
          <geometry>
            <mesh>
              <scale>1 1 1</scale>
              <uri>/home/andi/catkin_redevel_ws/src/ugv_gazebo_sim/bunker/bunker_description/meshes/wheel1.2_Link.STL</uri>
            </mesh>
          </geometry>
          <max_contacts>10</max_contacts>
          <surface>
            <contact>
              <ode/>
            </contact>
            <bounce/>
            <friction>
              <torsional>
                <ode/>
              </torsional>
              <ode/>
            </friction>
          </surface>
        </collision>
        <visual name='wheel1.2_Link_visual'>
          <pose frame=''>0 0 0 0 -0 0</pose>
          <geometry>
            <mesh>
              <scale>1 1 1</scale>
              <uri>/home/andi/catkin_redevel_ws/src/ugv_gazebo_sim/bunker/bunker_description/meshes/wheel1.2_Link.STL</uri>
            </mesh>
          </geometry>
        </visual>
        <self_collide>0</self_collide>
        <enable_wind>0</enable_wind>
        <kinematic>0</kinematic>
      </link>
      <joint name='wheel1.2_joint' type='revolute'>
        <child>wheel1.2_Link</child>
        <parent>robot_base</parent>
        <axis>
          <xyz>7e-06 1 -4e-06</xyz>
          <limit>
            <lower>-180</lower>
            <upper>180</upper>
            <effort>0</effort>
            <velocity>0</velocity>
          </limit>
          <dynamics>
            <spring_reference>0</spring_reference>
            <spring_stiffness>0</spring_stiffness>
          </dynamics>
          <use_parent_model_frame>1</use_parent_model_frame>
        </axis>
      </joint>
      <link name='wheel1.3_Link'>
        <pose frame=''>0.29603 0.3495 -0.087 1.5708 -0 3.14159</pose>
        <inertial>
          <pose frame=''>3.4e-05 -2.7e-05 -0.07015 0 -0 0</pose>
          <mass>0.0001</mass>
          <inertia>
            <ixx>0.000105254</ixx>
            <ixy>1.32328e-08</ixy>
            <ixz>3.84295e-11</ixz>
            <iyy>0.000105249</iyy>
            <iyz>-1.41156e-11</iyz>
            <izz>0.000173281</izz>
          </inertia>
        </inertial>
        <collision name='wheel1.3_Link_collision'>
          <pose frame=''>0 0 0 0 -0 0</pose>
          <geometry>
            <mesh>
              <scale>1 1 1</scale>
              <uri>/home/andi/catkin_redevel_ws/src/ugv_gazebo_sim/bunker/bunker_description/meshes/wheel1.3_Link.STL</uri>
            </mesh>
          </geometry>
          <max_contacts>10</max_contacts>
          <surface>
            <contact>
              <ode/>
            </contact>
            <bounce/>
            <friction>
              <torsional>
                <ode/>
              </torsional>
              <ode/>
            </friction>
          </surface>
        </collision>
        <visual name='wheel1.3_Link_visual'>
          <pose frame=''>0 0 0 0 -0 0</pose>
          <geometry>
            <mesh>
              <scale>1 1 1</scale>
              <uri>/home/andi/catkin_redevel_ws/src/ugv_gazebo_sim/bunker/bunker_description/meshes/wheel1.3_Link.STL</uri>
            </mesh>
          </geometry>
        </visual>
        <self_collide>0</self_collide>
        <enable_wind>0</enable_wind>
        <kinematic>0</kinematic>
      </link>
      <joint name='wheel1.3_joint' type='revolute'>
        <child>wheel1.3_Link</child>
        <parent>robot_base</parent>
        <axis>
          <xyz>-7e-06 -1 4e-06</xyz>
          <limit>
            <lower>-180</lower>
            <upper>180</upper>
            <effort>0</effort>
            <velocity>0</velocity>
          </limit>
          <dynamics>
            <spring_reference>0</spring_reference>
            <spring_stiffness>0</spring_stiffness>
          </dynamics>
          <use_parent_model_frame>1</use_parent_model_frame>
        </axis>
      </joint>
      <link name='wheel1_Link'>
        <pose frame=''>0.44403 0.3495 -0.12853 1.5708 -0 3.14159</pose>
        <inertial>
          <pose frame=''>0 -0 -0.072 0 -0 0</pose>
          <mass>0.0001</mass>
          <inertia>
            <ixx>0.000378441</ixx>
            <ixy>5.60823e-21</ixy>
            <ixz>3.04208e-20</ixz>
            <iyy>0.000378441</iyy>
            <iyz>-7.56627e-21</iyz>
            <izz>0.000710151</izz>
          </inertia>
        </inertial>
        <collision name='wheel1_Link_collision'>
          <pose frame=''>0 0 0 0 -0 0</pose>
          <geometry>
            <mesh>
              <scale>1 1 1</scale>
              <uri>/home/andi/catkin_redevel_ws/src/ugv_gazebo_sim/bunker/bunker_description/meshes/wheel1_Link.STL</uri>
            </mesh>
          </geometry>
          <max_contacts>10</max_contacts>
          <surface>
            <contact>
              <ode/>
            </contact>
            <bounce/>
            <friction>
              <torsional>
                <ode/>
              </torsional>
              <ode/>
            </friction>
          </surface>
        </collision>
        <visual name='wheel1_Link_visual'>
          <pose frame=''>0 0 0 0 -0 0</pose>
          <geometry>
            <mesh>
              <scale>1 1 1</scale>
              <uri>/home/andi/catkin_redevel_ws/src/ugv_gazebo_sim/bunker/bunker_description/meshes/wheel1_Link.STL</uri>
            </mesh>
          </geometry>
        </visual>
        <self_collide>0</self_collide>
        <enable_wind>0</enable_wind>
        <kinematic>0</kinematic>
      </link>
      <joint name='wheel1_joint' type='revolute'>
        <child>wheel1_Link</child>
        <parent>robot_base</parent>
        <axis>
          <xyz>7e-06 1 -4e-06</xyz>
          <limit>
            <lower>-180</lower>
            <upper>180</upper>
            <effort>0</effort>
            <velocity>0</velocity>
          </limit>
          <dynamics>
            <spring_reference>0</spring_reference>
            <spring_stiffness>0</spring_stiffness>
          </dynamics>
          <use_parent_model_frame>1</use_parent_model_frame>
        </axis>
      </joint>
      <link name='wheel2.1_Link'>
        <pose frame=''>0.37551 -0.3495 -0.22305 1.5708 -0 3.14159</pose>
        <inertial>
          <pose frame=''>-0 0 0.072 0 -0 0</pose>
          <mass>0.0001</mass>
          <inertia>
            <ixx>6.58751e-05</ixx>
            <ixy>-1.46559e-09</ixy>
            <ixz>-8.34967e-12</ixz>
            <iyy>6.58796e-05</iyy>
            <iyz>-2.4786e-12</iyz>
            <izz>0.000112722</izz>
          </inertia>
        </inertial>
        <collision name='wheel2.1_Link_collision'>
          <pose frame=''>0 0 0 0 -0 0</pose>
          <geometry>
            <mesh>
              <scale>1 1 1</scale>
              <uri>/home/andi/catkin_redevel_ws/src/ugv_gazebo_sim/bunker/bunker_description/meshes/wheel2.1_Link.STL</uri>
            </mesh>
          </geometry>
          <max_contacts>10</max_contacts>
          <surface>
            <contact>
              <ode/>
            </contact>
            <bounce/>
            <friction>
              <torsional>
                <ode/>
              </torsional>
              <ode/>
            </friction>
          </surface>
        </collision>
        <visual name='wheel2.1_Link_visual'>
          <pose frame=''>0 0 0 0 -0 0</pose>
          <geometry>
            <mesh>
              <scale>1 1 1</scale>
              <uri>/home/andi/catkin_redevel_ws/src/ugv_gazebo_sim/bunker/bunker_description/meshes/wheel2.1_Link.STL</uri>
            </mesh>
          </geometry>
        </visual>
        <self_collide>0</self_collide>
        <enable_wind>0</enable_wind>
        <kinematic>0</kinematic>
      </link>
      <joint name='wheel2.1_joint' type='revolute'>
        <child>wheel2.1_Link</child>
        <parent>robot_base</parent>
        <axis>
          <xyz>-7e-06 -1 4e-06</xyz>
          <limit>
            <lower>-180</lower>
            <upper>180</upper>
            <effort>0</effort>
            <velocity>0</velocity>
          </limit>
          <dynamics>
            <spring_reference>0</spring_reference>
            <spring_stiffness>0</spring_stiffness>
          </dynamics>
          <use_parent_model_frame>1</use_parent_model_frame>
        </axis>
      </joint>
      <link name='wheel2.2_Link'>
        <pose frame=''>0.29039 -0.3495 -0.28104 1.5708 -0 3.14159</pose>
        <inertial>
          <pose frame=''>-0 -0 0.072 0 -0 0</pose>
          <mass>0.0001</mass>
          <inertia>
            <ixx>0.000179574</ixx>
            <ixy>6.2896e-21</ixy>
            <ixz>2.14011e-21</ixz>
            <iyy>0.000179574</iyy>
            <iyz>1.2771e-22</iyz>
            <izz>0.000332595</izz>
          </inertia>
        </inertial>
        <collision name='wheel2.2_Link_collision'>
          <pose frame=''>0 0 0 0 -0 0</pose>
          <geometry>
            <mesh>
              <scale>1 1 1</scale>
              <uri>/home/andi/catkin_redevel_ws/src/ugv_gazebo_sim/bunker/bunker_description/meshes/wheel2.2_Link.STL</uri>
            </mesh>
          </geometry>
          <max_contacts>10</max_contacts>
          <surface>
            <contact>
              <ode/>
            </contact>
            <bounce/>
            <friction>
              <torsional>
                <ode/>
              </torsional>
              <ode/>
            </friction>
          </surface>
        </collision>
        <visual name='wheel2.2_Link_visual'>
          <pose frame=''>0 0 0 0 -0 0</pose>
          <geometry>
            <mesh>
              <scale>1 1 1</scale>
              <uri>/home/andi/catkin_redevel_ws/src/ugv_gazebo_sim/bunker/bunker_description/meshes/wheel2.2_Link.STL</uri>
            </mesh>
          </geometry>
        </visual>
        <self_collide>0</self_collide>
        <enable_wind>0</enable_wind>
        <kinematic>0</kinematic>
      </link>
      <joint name='wheel2.2_joint' type='revolute'>
        <child>wheel2.2_Link</child>
        <parent>robot_base</parent>
        <axis>
          <xyz>-7e-06 -1 4e-06</xyz>
          <limit>
            <lower>-180</lower>
            <upper>180</upper>
            <effort>0</effort>
            <velocity>0</velocity>
          </limit>
          <dynamics>
            <spring_reference>0</spring_reference>
            <spring_stiffness>0</spring_stiffness>
          </dynamics>
          <use_parent_model_frame>1</use_parent_model_frame>
        </axis>
      </joint>
      <link name='wheel2.3_Link'>
        <pose frame=''>0.29603 -0.3495 -0.087 1.5708 -0 3.14159</pose>
        <inertial>
          <pose frame=''>3.5e-05 -2.7e-05 0.070928 0 -0 0</pose>
          <mass>0.0001</mass>
          <inertia>
            <ixx>0.000105035</ixx>
            <ixy>1.32328e-08</ixy>
            <ixz>3.84295e-11</ixz>
            <iyy>0.00010503</iyy>
            <iyz>-1.41156e-11</iyz>
            <izz>0.000172982</izz>
          </inertia>
        </inertial>
        <collision name='wheel2.3_Link_collision'>
          <pose frame=''>0 0 0 0 -0 0</pose>
          <geometry>
            <mesh>
              <scale>1 1 1</scale>
              <uri>/home/andi/catkin_redevel_ws/src/ugv_gazebo_sim/bunker/bunker_description/meshes/wheel2.3_Link.STL</uri>
            </mesh>
          </geometry>
          <max_contacts>10</max_contacts>
          <surface>
            <contact>
              <ode/>
            </contact>
            <bounce/>
            <friction>
              <torsional>
                <ode/>
              </torsional>
              <ode/>
            </friction>
          </surface>
        </collision>
        <visual name='wheel2.3_Link_visual'>
          <pose frame=''>0 0 0 0 -0 0</pose>
          <geometry>
            <mesh>
              <scale>1 1 1</scale>
              <uri>/home/andi/catkin_redevel_ws/src/ugv_gazebo_sim/bunker/bunker_description/meshes/wheel2.3_Link.STL</uri>
            </mesh>
          </geometry>
        </visual>
        <self_collide>0</self_collide>
        <enable_wind>0</enable_wind>
        <kinematic>0</kinematic>
      </link>
      <joint name='wheel2.3_joint' type='revolute'>
        <child>wheel2.3_Link</child>
        <parent>robot_base</parent>
        <axis>
          <xyz>7e-06 1 -4e-06</xyz>
          <limit>
            <lower>-180</lower>
            <upper>180</upper>
            <effort>0</effort>
            <velocity>0</velocity>
          </limit>
          <dynamics>
            <spring_reference>0</spring_reference>
            <spring_stiffness>0</spring_stiffness>
          </dynamics>
          <use_parent_model_frame>1</use_parent_model_frame>
        </axis>
      </joint>
      <link name='wheel2_Link'>
        <pose frame=''>0.44403 -0.3495 -0.12853 1.5708 -0 3.14159</pose>
        <inertial>
          <pose frame=''>-0 0 0.072 0 -0 0</pose>
          <mass>0.0001</mass>
          <inertia>
            <ixx>0.000378441</ixx>
            <ixy>3.37302e-21</ixy>
            <ixz>2.71827e-20</ixz>
            <iyy>0.000378441</iyy>
            <iyz>-7.32822e-21</iyz>
            <izz>0.000710151</izz>
          </inertia>
        </inertial>
        <collision name='wheel2_Link_collision'>
          <pose frame=''>0 0 0 0 -0 0</pose>
          <geometry>
            <mesh>
              <scale>1 1 1</scale>
              <uri>/home/andi/catkin_redevel_ws/src/ugv_gazebo_sim/bunker/bunker_description/meshes/wheel2_Link.STL</uri>
            </mesh>
          </geometry>
          <max_contacts>10</max_contacts>
          <surface>
            <contact>
              <ode/>
            </contact>
            <bounce/>
            <friction>
              <torsional>
                <ode/>
              </torsional>
              <ode/>
            </friction>
          </surface>
        </collision>
        <visual name='wheel2_Link_visual'>
          <pose frame=''>0 0 0 0 -0 0</pose>
          <geometry>
            <mesh>
              <scale>1 1 1</scale>
              <uri>/home/andi/catkin_redevel_ws/src/ugv_gazebo_sim/bunker/bunker_description/meshes/wheel2_Link.STL</uri>
            </mesh>
          </geometry>
        </visual>
        <self_collide>0</self_collide>
        <enable_wind>0</enable_wind>
        <kinematic>0</kinematic>
      </link>
      <joint name='wheel2_joint' type='revolute'>
        <child>wheel2_Link</child>
        <parent>robot_base</parent>
        <axis>
          <xyz>-7e-06 -1 4e-06</xyz>
          <limit>
            <lower>-180</lower>
            <upper>180</upper>
            <effort>0</effort>
            <velocity>0</velocity>
          </limit>
          <dynamics>
            <spring_reference>0</spring_reference>
            <spring_stiffness>0</spring_stiffness>
          </dynamics>
          <use_parent_model_frame>1</use_parent_model_frame>
        </axis>
      </joint>
      <link name='wheel3.1_Link'>
        <pose frame=''>-0.23111 0.3495 -0.27671 1.5708 -0 3.14159</pose>
        <inertial>
          <pose frame=''>0 0 -0.072 0 -0 0</pose>
          <mass>0.0001</mass>
          <inertia>
            <ixx>0.000179574</ixx>
            <ixy>-1.73824e-20</ixy>
            <ixz>-2.5316e-21</ixz>
            <iyy>0.000179574</iyy>
            <iyz>-3.13741e-21</iyz>
            <izz>0.000332595</izz>
          </inertia>
        </inertial>
        <collision name='wheel3.1_Link_collision'>
          <pose frame=''>0 0 0 0 -0 0</pose>
          <geometry>
            <mesh>
              <scale>1 1 1</scale>
              <uri>/home/andi/catkin_redevel_ws/src/ugv_gazebo_sim/bunker/bunker_description/meshes/wheel3.1_Link.STL</uri>
            </mesh>
          </geometry>
          <max_contacts>10</max_contacts>
          <surface>
            <contact>
              <ode/>
            </contact>
            <bounce/>
            <friction>
              <torsional>
                <ode/>
              </torsional>
              <ode/>
            </friction>
          </surface>
        </collision>
        <visual name='wheel3.1_Link_visual'>
          <pose frame=''>0 0 0 0 -0 0</pose>
          <geometry>
            <mesh>
              <scale>1 1 1</scale>
              <uri>/home/andi/catkin_redevel_ws/src/ugv_gazebo_sim/bunker/bunker_description/meshes/wheel3.1_Link.STL</uri>
            </mesh>
          </geometry>
        </visual>
        <self_collide>0</self_collide>
        <enable_wind>0</enable_wind>
        <kinematic>0</kinematic>
      </link>
      <joint name='wheel3.1_joint' type='revolute'>
        <child>wheel3.1_Link</child>
        <parent>robot_base</parent>
        <axis>
          <xyz>7e-06 1 -4e-06</xyz>
          <limit>
            <lower>-180</lower>
            <upper>180</upper>
            <effort>0</effort>
            <velocity>0</velocity>
          </limit>
          <dynamics>
            <spring_reference>0</spring_reference>
            <spring_stiffness>0</spring_stiffness>
          </dynamics>
          <use_parent_model_frame>1</use_parent_model_frame>
        </axis>
      </joint>
      <link name='wheel3.2_Link'>
        <pose frame=''>0.043885 0.3495 -0.27671 1.5708 -0 3.14159</pose>
        <inertial>
          <pose frame=''>0 0 -0.072 0 -0 0</pose>
          <mass>0.0001</mass>
          <inertia>
            <ixx>0.000179574</ixx>
            <ixy>9.82929e-22</ixy>
            <ixz>1.1099e-21</ixz>
            <iyy>0.000179574</iyy>
            <iyz>-4.81322e-21</iyz>
            <izz>0.000332595</izz>
          </inertia>
        </inertial>
        <collision name='wheel3.2_Link_collision'>
          <pose frame=''>0 0 0 0 -0 0</pose>
          <geometry>
            <mesh>
              <scale>1 1 1</scale>
              <uri>/home/andi/catkin_redevel_ws/src/ugv_gazebo_sim/bunker/bunker_description/meshes/wheel3.2_Link.STL</uri>
            </mesh>
          </geometry>
          <max_contacts>10</max_contacts>
          <surface>
            <contact>
              <ode/>
            </contact>
            <bounce/>
            <friction>
              <torsional>
                <ode/>
              </torsional>
              <ode/>
            </friction>
          </surface>
        </collision>
        <visual name='wheel3.2_Link_visual'>
          <pose frame=''>0 0 0 0 -0 0</pose>
          <geometry>
            <mesh>
              <scale>1 1 1</scale>
              <uri>/home/andi/catkin_redevel_ws/src/ugv_gazebo_sim/bunker/bunker_description/meshes/wheel3.2_Link.STL</uri>
            </mesh>
          </geometry>
        </visual>
        <self_collide>0</self_collide>
        <enable_wind>0</enable_wind>
        <kinematic>0</kinematic>
      </link>
      <joint name='wheel3.2_joint' type='revolute'>
        <child>wheel3.2_Link</child>
        <parent>robot_base</parent>
        <axis>
          <xyz>7e-06 1 -4e-06</xyz>
          <limit>
            <lower>-180</lower>
            <upper>180</upper>
            <effort>0</effort>
            <velocity>0</velocity>
          </limit>
          <dynamics>
            <spring_reference>0</spring_reference>
            <spring_stiffness>0</spring_stiffness>
          </dynamics>
          <use_parent_model_frame>1</use_parent_model_frame>
        </axis>
      </joint>
      <link name='wheel3.3_Link'>
        <pose frame=''>-0.28597 0.3495 -0.087 1.5708 -0 3.14159</pose>
        <inertial>
          <pose frame=''>0 -5.3e-05 -0.07015 0 -0 0</pose>
          <mass>0.0001</mass>
          <inertia>
            <ixx>0.000105265</ixx>
            <ixy>7.98232e-12</ixy>
            <ixz>6.804e-11</ixz>
            <iyy>0.000105238</iyy>
            <iyz>-2.72106e-11</iyz>
            <izz>0.000173281</izz>
          </inertia>
        </inertial>
        <collision name='wheel3.3_Link_collision'>
          <pose frame=''>0 0 0 0 -0 0</pose>
          <geometry>
            <mesh>
              <scale>1 1 1</scale>
              <uri>/home/andi/catkin_redevel_ws/src/ugv_gazebo_sim/bunker/bunker_description/meshes/wheel3.3_Link.STL</uri>
            </mesh>
          </geometry>
          <max_contacts>10</max_contacts>
          <surface>
            <contact>
              <ode/>
            </contact>
            <bounce/>
            <friction>
              <torsional>
                <ode/>
              </torsional>
              <ode/>
            </friction>
          </surface>
        </collision>
        <visual name='wheel3.3_Link_visual'>
          <pose frame=''>0 0 0 0 -0 0</pose>
          <geometry>
            <mesh>
              <scale>1 1 1</scale>
              <uri>/home/andi/catkin_redevel_ws/src/ugv_gazebo_sim/bunker/bunker_description/meshes/wheel3.3_Link.STL</uri>
            </mesh>
          </geometry>
        </visual>
        <self_collide>0</self_collide>
        <enable_wind>0</enable_wind>
        <kinematic>0</kinematic>
      </link>
      <joint name='wheel3.3_joint' type='revolute'>
        <child>wheel3.3_Link</child>
        <parent>robot_base</parent>
        <axis>
          <xyz>-7e-06 -1 4e-06</xyz>
          <limit>
            <lower>-180</lower>
            <upper>180</upper>
            <effort>0</effort>
            <velocity>0</velocity>
          </limit>
          <dynamics>
            <spring_reference>0</spring_reference>
            <spring_stiffness>0</spring_stiffness>
          </dynamics>
          <use_parent_model_frame>1</use_parent_model_frame>
        </axis>
      </joint>
      <link name='wheel3_Link'>
        <pose frame=''>-0.38871 0.295 -0.19381 1.5708 -0 3.14159</pose>
        <inertial>
          <pose frame=''>-0 0 -0.024606 0 -0 0</pose>
          <mass>0.0001</mass>
          <inertia>
            <ixx>0.00232456</ixx>
            <ixy>-1.61343e-09</ixy>
            <ixz>-4.56707e-13</ixz>
            <iyy>0.00232457</iyy>
            <iyz>-1.36036e-18</iyz>
            <izz>0.00308348</izz>
          </inertia>
        </inertial>
        <collision name='wheel3_Link_collision'>
          <pose frame=''>0 0 0 0 -0 0</pose>
          <geometry>
            <mesh>
              <scale>1 1 1</scale>
              <uri>/home/andi/catkin_redevel_ws/src/ugv_gazebo_sim/bunker/bunker_description/meshes/wheel3_Link.STL</uri>
            </mesh>
          </geometry>
          <max_contacts>10</max_contacts>
          <surface>
            <contact>
              <ode/>
            </contact>
            <bounce/>
            <friction>
              <torsional>
                <ode/>
              </torsional>
              <ode/>
            </friction>
          </surface>
        </collision>
        <visual name='wheel3_Link_visual'>
          <pose frame=''>0 0 0 0 -0 0</pose>
          <geometry>
            <mesh>
              <scale>1 1 1</scale>
              <uri>/home/andi/catkin_redevel_ws/src/ugv_gazebo_sim/bunker/bunker_description/meshes/wheel3_Link.STL</uri>
            </mesh>
          </geometry>
        </visual>
        <self_collide>0</self_collide>
        <enable_wind>0</enable_wind>
        <kinematic>0</kinematic>
      </link>
      <joint name='wheel3_joint' type='revolute'>
        <child>wheel3_Link</child>
        <parent>robot_base</parent>
        <axis>
          <xyz>-7e-06 -1 4e-06</xyz>
          <limit>
            <lower>-180</lower>
            <upper>180</upper>
            <effort>0</effort>
            <velocity>0</velocity>
          </limit>
          <dynamics>
            <spring_reference>0</spring_reference>
            <spring_stiffness>0</spring_stiffness>
          </dynamics>
          <use_parent_model_frame>1</use_parent_model_frame>
        </axis>
      </joint>
      <link name='wheel4.1_Link'>
        <pose frame=''>-0.23111 -0.3495 -0.27671 1.5708 -0 3.14159</pose>
        <inertial>
          <pose frame=''>-0 -0 0.072 0 -0 0</pose>
          <mass>0.0001</mass>
          <inertia>
            <ixx>0.000179574</ixx>
            <ixy>-7.93399e-21</ixy>
            <ixz>-2.13342e-21</ixz>
            <iyy>0.000179574</iyy>
            <iyz>-3.23624e-21</iyz>
            <izz>0.000332595</izz>
          </inertia>
        </inertial>
        <collision name='wheel4.1_Link_collision'>
          <pose frame=''>0 0 0 0 -0 0</pose>
          <geometry>
            <mesh>
              <scale>1 1 1</scale>
              <uri>/home/andi/catkin_redevel_ws/src/ugv_gazebo_sim/bunker/bunker_description/meshes/wheel4.1_Link.STL</uri>
            </mesh>
          </geometry>
          <max_contacts>10</max_contacts>
          <surface>
            <contact>
              <ode/>
            </contact>
            <bounce/>
            <friction>
              <torsional>
                <ode/>
              </torsional>
              <ode/>
            </friction>
          </surface>
        </collision>
        <visual name='wheel4.1_Link_visual'>
          <pose frame=''>0 0 0 0 -0 0</pose>
          <geometry>
            <mesh>
              <scale>1 1 1</scale>
              <uri>/home/andi/catkin_redevel_ws/src/ugv_gazebo_sim/bunker/bunker_description/meshes/wheel4.1_Link.STL</uri>
            </mesh>
          </geometry>
        </visual>
        <self_collide>0</self_collide>
        <enable_wind>0</enable_wind>
        <kinematic>0</kinematic>
      </link>
      <joint name='wheel4.1_joint' type='revolute'>
        <child>wheel4.1_Link</child>
        <parent>robot_base</parent>
        <axis>
          <xyz>-7e-06 -1 4e-06</xyz>
          <limit>
            <lower>-180</lower>
            <upper>180</upper>
            <effort>0</effort>
            <velocity>0</velocity>
          </limit>
          <dynamics>
            <spring_reference>0</spring_reference>
            <spring_stiffness>0</spring_stiffness>
          </dynamics>
          <use_parent_model_frame>1</use_parent_model_frame>
        </axis>
      </joint>
      <link name='wheel4.2_Link'>
        <pose frame=''>0.043885 -0.3495 -0.27671 1.5708 -0 3.14159</pose>
        <inertial>
          <pose frame=''>-0 -0 0.072 0 -0 0</pose>
          <mass>0.0001</mass>
          <inertia>
            <ixx>0.000179574</ixx>
            <ixy>6.30058e-22</ixy>
            <ixz>1.17534e-22</ixz>
            <iyy>0.000179574</iyy>
            <iyz>-3.27347e-21</iyz>
            <izz>0.000332595</izz>
          </inertia>
        </inertial>
        <collision name='wheel4.2_Link_collision'>
          <pose frame=''>0 0 0 0 -0 0</pose>
          <geometry>
            <mesh>
              <scale>1 1 1</scale>
              <uri>/home/andi/catkin_redevel_ws/src/ugv_gazebo_sim/bunker/bunker_description/meshes/wheel4.2_Link.STL</uri>
            </mesh>
          </geometry>
          <max_contacts>10</max_contacts>
          <surface>
            <contact>
              <ode/>
            </contact>
            <bounce/>
            <friction>
              <torsional>
                <ode/>
              </torsional>
              <ode/>
            </friction>
          </surface>
        </collision>
        <visual name='wheel4.2_Link_visual'>
          <pose frame=''>0 0 0 0 -0 0</pose>
          <geometry>
            <mesh>
              <scale>1 1 1</scale>
              <uri>/home/andi/catkin_redevel_ws/src/ugv_gazebo_sim/bunker/bunker_description/meshes/wheel4.2_Link.STL</uri>
            </mesh>
          </geometry>
        </visual>
        <self_collide>0</self_collide>
        <enable_wind>0</enable_wind>
        <kinematic>0</kinematic>
      </link>
      <joint name='wheel4.2_joint' type='revolute'>
        <child>wheel4.2_Link</child>
        <parent>robot_base</parent>
        <axis>
          <xyz>-7e-06 -1 4e-06</xyz>
          <limit>
            <lower>-180</lower>
            <upper>180</upper>
            <effort>0</effort>
            <velocity>0</velocity>
          </limit>
          <dynamics>
            <spring_reference>0</spring_reference>
            <spring_stiffness>0</spring_stiffness>
          </dynamics>
          <use_parent_model_frame>1</use_parent_model_frame>
        </axis>
      </joint>
      <link name='wheel4.3_Link'>
        <pose frame=''>-0.28597 -0.3495 -0.087 1.5708 -0 3.14159</pose>
        <inertial>
          <pose frame=''>0 -5.3e-05 0.070115 0 -0 0</pose>
          <mass>0.0001</mass>
          <inertia>
            <ixx>0.000105265</ixx>
            <ixy>7.98232e-12</ixy>
            <ixz>6.804e-11</ixz>
            <iyy>0.000105238</iyy>
            <iyz>-2.72106e-11</iyz>
            <izz>0.000173281</izz>
          </inertia>
        </inertial>
        <collision name='wheel4.3_Link_collision'>
          <pose frame=''>0 0 0 0 -0 0</pose>
          <geometry>
            <mesh>
              <scale>1 1 1</scale>
              <uri>/home/andi/catkin_redevel_ws/src/ugv_gazebo_sim/bunker/bunker_description/meshes/wheel4.3_Link.STL</uri>
            </mesh>
          </geometry>
          <max_contacts>10</max_contacts>
          <surface>
            <contact>
              <ode/>
            </contact>
            <bounce/>
            <friction>
              <torsional>
                <ode/>
              </torsional>
              <ode/>
            </friction>
          </surface>
        </collision>
        <visual name='wheel4.3_Link_visual'>
          <pose frame=''>0 0 0 0 -0 0</pose>
          <geometry>
            <mesh>
              <scale>1 1 1</scale>
              <uri>/home/andi/catkin_redevel_ws/src/ugv_gazebo_sim/bunker/bunker_description/meshes/wheel4.3_Link.STL</uri>
            </mesh>
          </geometry>
        </visual>
        <self_collide>0</self_collide>
        <enable_wind>0</enable_wind>
        <kinematic>0</kinematic>
      </link>
      <joint name='wheel4.3_joint' type='revolute'>
        <child>wheel4.3_Link</child>
        <parent>robot_base</parent>
        <axis>
          <xyz>7e-06 1 -4e-06</xyz>
          <limit>
            <lower>-180</lower>
            <upper>180</upper>
            <effort>0</effort>
            <velocity>0</velocity>
          </limit>
          <dynamics>
            <spring_reference>0</spring_reference>
            <spring_stiffness>0</spring_stiffness>
          </dynamics>
          <use_parent_model_frame>1</use_parent_model_frame>
        </axis>
      </joint>
      <link name='wheel4_Link'>
        <pose frame=''>-0.38871 -0.295 -0.19381 1.5708 -0 3.14159</pose>
        <inertial>
          <pose frame=''>0 0 0.024593 0 -0 0</pose>
          <mass>0.0001</mass>
          <inertia>
            <ixx>0.00232457</ixx>
            <ixy>-1.61343e-09</ixy>
            <ixz>-3.67392e-19</ixz>
            <iyy>0.00232456</iyy>
            <iyz>-4.56707e-13</iyz>
            <izz>0.00308348</izz>
          </inertia>
        </inertial>
        <collision name='wheel4_Link_collision'>
          <pose frame=''>0 0 0 0 -0 0</pose>
          <geometry>
            <mesh>
              <scale>1 1 1</scale>
              <uri>/home/andi/catkin_redevel_ws/src/ugv_gazebo_sim/bunker/bunker_description/meshes/wheel4_Link.STL</uri>
            </mesh>
          </geometry>
          <max_contacts>10</max_contacts>
          <surface>
            <contact>
              <ode/>
            </contact>
            <bounce/>
            <friction>
              <torsional>
                <ode/>
              </torsional>
              <ode/>
            </friction>
          </surface>
        </collision>
        <visual name='wheel4_Link_visual'>
          <pose frame=''>0 0 0 0 -0 0</pose>
          <geometry>
            <mesh>
              <scale>1 1 1</scale>
              <uri>/home/andi/catkin_redevel_ws/src/ugv_gazebo_sim/bunker/bunker_description/meshes/wheel4_Link.STL</uri>
            </mesh>
          </geometry>
        </visual>
        <self_collide>0</self_collide>
        <enable_wind>0</enable_wind>
        <kinematic>0</kinematic>
      </link>
      <joint name='wheel4_joint' type='revolute'>
        <child>wheel4_Link</child>
        <parent>robot_base</parent>
        <axis>
          <xyz>7e-06 1 -4e-06</xyz>
          <limit>
            <lower>-180</lower>
            <upper>180</upper>
            <effort>0</effort>
            <velocity>0</velocity>
          </limit>
          <dynamics>
            <spring_reference>0</spring_reference>
            <spring_stiffness>0</spring_stiffness>
          </dynamics>
          <use_parent_model_frame>1</use_parent_model_frame>
        </axis>
      </joint>
      <plugin name='object_controller' filename='libgazebo_ros_planar_move.so'>
        <commandTopic>smoother_cmd_vel</commandTopic>
        <odometryTopic>odom</odometryTopic>
        <odometryFrame>odom</odometryFrame>
        <odometryRate>20.0</odometryRate>
        <leftFrontJoint>wheel1_2_joint</leftFrontJoint>
        <rightFrontJoint>wheel2_2_joint</rightFrontJoint>
        <leftRearJoint>wheel3_1_joint</leftRearJoint>
        <rightRearJoint>wheel4_1_joint</rightRearJoint>
        <robotBaseFrame>robot_base</robotBaseFrame>
        <robotNamespace>/</robotNamespace>
      </plugin>
      <plugin name='gazebo_ros_control' filename='libgazebo_ros_control.so'>
        <robotSimType>gazebo_ros_control/DefaultRobotHWSim</robotSimType>
        <legacyModeNS>1</legacyModeNS>
        <robotNamespace>/</robotNamespace>
      </plugin>
      <plugin name='gps_controller' filename='libhector_gazebo_ros_gps.so'>
        <updateRate>40</updateRate>
        <bodyName>robot_base</bodyName>
        <frameId>robot_base</frameId>
        <topicName>ublox_gps/fix</topicName>
        <velocityTopicName>ublox_gps/vel</velocityTopicName>
        <referenceLatitude>49.9</referenceLatitude>
        <referenceLongitude>8.9</referenceLongitude>
        <referenceHeading>0</referenceHeading>
        <referenceAltitude>0</referenceAltitude>
        <drift>0.0001 0.0001 0.0001</drift>
        <robotNamespace>/</robotNamespace>
      </plugin>
      <static>0</static>
      <plugin name='imu_controller' filename='libhector_gazebo_ros_imu.so'>
        <robotNamespace>/</robotNamespace>
        <updateRate>50.0</updateRate>
        <topicName>imu/data</topicName>
        <accelDrift>0.005 0.005 0.005</accelDrift>
        <accelGaussianNoise>0.005 0.005 0.005</accelGaussianNoise>
        <rateDrift>0.005 0.005 0.005</rateDrift>
        <rateGaussianNoise>0.005 0.005 0.005</rateGaussianNoise>
        <headingDrift>0.005</headingDrift>
        <headingGaussianNoise>0.005</headingGaussianNoise>
        <bodyName>robot_base</bodyName>
        <xyzOffset>-0.33 0.065 -0.29</xyzOffset>
        <rpyOffset>0 -0 0</rpyOffset>
      </plugin>
      <pose frame=''>0 0 0 0 -0 0</pose>
    </model>
    <model name='unit_cylinder'>
      <pose frame=''>2.46552 1.50285 0.5 0 -0 0</pose>
      <link name='link'>
        <inertial>
          <mass>1</mass>
          <inertia>
            <ixx>0.145833</ixx>
            <ixy>0</ixy>
            <ixz>0</ixz>
            <iyy>0.145833</iyy>
            <iyz>0</iyz>
            <izz>0.125</izz>
          </inertia>
        </inertial>
        <collision name='collision'>
          <geometry>
            <cylinder>
              <radius>0.5</radius>
              <length>1</length>
            </cylinder>
          </geometry>
          <max_contacts>10</max_contacts>
          <surface>
            <contact>
              <ode/>
            </contact>
            <bounce/>
            <friction>
              <torsional>
                <ode/>
              </torsional>
              <ode/>
            </friction>
          </surface>
        </collision>
        <visual name='visual'>
          <geometry>
            <cylinder>
              <radius>0.5</radius>
              <length>1</length>
            </cylinder>
          </geometry>
          <material>
            <script>
              <name>Gazebo/Grey</name>
              <uri>file://media/materials/scripts/gazebo.material</uri>
            </script>
          </material>
        </visual>
        <self_collide>0</self_collide>
        <enable_wind>0</enable_wind>
        <kinematic>0</kinematic>
      </link>
    </model>
    <model name='unit_cylinder_0'>
      <pose frame=''>2.39133 4.98227 0.5 0 -0 0</pose>
      <link name='link'>
        <inertial>
          <mass>1</mass>
          <inertia>
            <ixx>0.145833</ixx>
            <ixy>0</ixy>
            <ixz>0</ixz>
            <iyy>0.145833</iyy>
            <iyz>0</iyz>
            <izz>0.125</izz>
          </inertia>
        </inertial>
        <collision name='collision'>
          <geometry>
            <cylinder>
              <radius>0.5</radius>
              <length>1</length>
            </cylinder>
          </geometry>
          <max_contacts>10</max_contacts>
          <surface>
            <contact>
              <ode/>
            </contact>
            <bounce/>
            <friction>
              <torsional>
                <ode/>
              </torsional>
              <ode/>
            </friction>
          </surface>
        </collision>
        <visual name='visual'>
          <geometry>
            <cylinder>
              <radius>0.5</radius>
              <length>1</length>
            </cylinder>
          </geometry>
          <material>
            <script>
              <name>Gazebo/Grey</name>
              <uri>file://media/materials/scripts/gazebo.material</uri>
            </script>
          </material>
        </visual>
        <self_collide>0</self_collide>
        <enable_wind>0</enable_wind>
        <kinematic>0</kinematic>
      </link>
    </model>
    <model name='unit_cylinder_1'>
      <pose frame=''>6.43858 1.49488 0.5 0 -0 0</pose>
      <link name='link'>
        <inertial>
          <mass>1</mass>
          <inertia>
            <ixx>0.145833</ixx>
            <ixy>0</ixy>
            <ixz>0</ixz>
            <iyy>0.145833</iyy>
            <iyz>0</iyz>
            <izz>0.125</izz>
          </inertia>
        </inertial>
        <collision name='collision'>
          <geometry>
            <cylinder>
              <radius>0.5</radius>
              <length>1</length>
            </cylinder>
          </geometry>
          <max_contacts>10</max_contacts>
          <surface>
            <contact>
              <ode/>
            </contact>
            <bounce/>
            <friction>
              <torsional>
                <ode/>
              </torsional>
              <ode/>
            </friction>
          </surface>
        </collision>
        <visual name='visual'>
          <geometry>
            <cylinder>
              <radius>0.5</radius>
              <length>1</length>
            </cylinder>
          </geometry>
          <material>
            <script>
              <name>Gazebo/Grey</name>
              <uri>file://media/materials/scripts/gazebo.material</uri>
            </script>
          </material>
        </visual>
        <self_collide>0</self_collide>
        <enable_wind>0</enable_wind>
        <kinematic>0</kinematic>
      </link>
    </model>
    <model name='unit_cylinder_2'>
      <pose frame=''>10.5304 1.45072 0.5 0 -0 0</pose>
      <link name='link'>
        <inertial>
          <mass>1</mass>
          <inertia>
            <ixx>0.145833</ixx>
            <ixy>0</ixy>
            <ixz>0</ixz>
            <iyy>0.145833</iyy>
            <iyz>0</iyz>
            <izz>0.125</izz>
          </inertia>
        </inertial>
        <collision name='collision'>
          <geometry>
            <cylinder>
              <radius>0.5</radius>
              <length>1</length>
            </cylinder>
          </geometry>
          <max_contacts>10</max_contacts>
          <surface>
            <contact>
              <ode/>
            </contact>
            <bounce/>
            <friction>
              <torsional>
                <ode/>
              </torsional>
              <ode/>
            </friction>
          </surface>
        </collision>
        <visual name='visual'>
          <geometry>
            <cylinder>
              <radius>0.5</radius>
              <length>1</length>
            </cylinder>
          </geometry>
          <material>
            <script>
              <name>Gazebo/Grey</name>
              <uri>file://media/materials/scripts/gazebo.material</uri>
            </script>
          </material>
        </visual>
        <self_collide>0</self_collide>
        <enable_wind>0</enable_wind>
        <kinematic>0</kinematic>
      </link>
    </model>
    <model name='unit_cylinder_3'>
      <pose frame=''>6.50042 5.02827 0.5 0 -0 0</pose>
      <link name='link'>
        <inertial>
          <mass>1</mass>
          <inertia>
            <ixx>0.145833</ixx>
            <ixy>0</ixy>
            <ixz>0</ixz>
            <iyy>0.145833</iyy>
            <iyz>0</iyz>
            <izz>0.125</izz>
          </inertia>
        </inertial>
        <collision name='collision'>
          <geometry>
            <cylinder>
              <radius>0.5</radius>
              <length>1</length>
            </cylinder>
          </geometry>
          <max_contacts>10</max_contacts>
          <surface>
            <contact>
              <ode/>
            </contact>
            <bounce/>
            <friction>
              <torsional>
                <ode/>
              </torsional>
              <ode/>
            </friction>
          </surface>
        </collision>
        <visual name='visual'>
          <geometry>
            <cylinder>
              <radius>0.5</radius>
              <length>1</length>
            </cylinder>
          </geometry>
          <material>
            <script>
              <name>Gazebo/Grey</name>
              <uri>file://media/materials/scripts/gazebo.material</uri>
            </script>
          </material>
        </visual>
        <self_collide>0</self_collide>
        <enable_wind>0</enable_wind>
        <kinematic>0</kinematic>
      </link>
    </model>
    <model name='unit_cylinder_4'>
      <pose frame=''>10.4721 5.01715 0.5 0 -0 0</pose>
      <link name='link'>
        <inertial>
          <mass>1</mass>
          <inertia>
            <ixx>0.145833</ixx>
            <ixy>0</ixy>
            <ixz>0</ixz>
            <iyy>0.145833</iyy>
            <iyz>0</iyz>
            <izz>0.125</izz>
          </inertia>
        </inertial>
        <collision name='collision'>
          <geometry>
            <cylinder>
              <radius>0.5</radius>
              <length>1</length>
            </cylinder>
          </geometry>
          <max_contacts>10</max_contacts>
          <surface>
            <contact>
              <ode/>
            </contact>
            <bounce/>
            <friction>
              <torsional>
                <ode/>
              </torsional>
              <ode/>
            </friction>
          </surface>
        </collision>
        <visual name='visual'>
          <geometry>
            <cylinder>
              <radius>0.5</radius>
              <length>1</length>
            </cylinder>
          </geometry>
          <material>
            <script>
              <name>Gazebo/Grey</name>
              <uri>file://media/materials/scripts/gazebo.material</uri>
            </script>
          </material>
        </visual>
        <self_collide>0</self_collide>
        <enable_wind>0</enable_wind>
        <kinematic>0</kinematic>
      </link>
    </model>
    <model name='unit_cylinder_5'>
      <pose frame=''>2.4295 8.37947 0.5 0 -0 0</pose>
      <link name='link'>
        <inertial>
          <mass>1</mass>
          <inertia>
            <ixx>0.145833</ixx>
            <ixy>0</ixy>
            <ixz>0</ixz>
            <iyy>0.145833</iyy>
            <iyz>0</iyz>
            <izz>0.125</izz>
          </inertia>
        </inertial>
        <collision name='collision'>
          <geometry>
            <cylinder>
              <radius>0.5</radius>
              <length>1</length>
            </cylinder>
          </geometry>
          <max_contacts>10</max_contacts>
          <surface>
            <contact>
              <ode/>
            </contact>
            <bounce/>
            <friction>
              <torsional>
                <ode/>
              </torsional>
              <ode/>
            </friction>
          </surface>
        </collision>
        <visual name='visual'>
          <geometry>
            <cylinder>
              <radius>0.5</radius>
              <length>1</length>
            </cylinder>
          </geometry>
          <material>
            <script>
              <name>Gazebo/Grey</name>
              <uri>file://media/materials/scripts/gazebo.material</uri>
            </script>
          </material>
        </visual>
        <self_collide>0</self_collide>
        <enable_wind>0</enable_wind>
        <kinematic>0</kinematic>
      </link>
    </model>
    <model name='unit_cylinder_6'>
      <pose frame=''>6.43133 8.38113 0.5 0 -0 0</pose>
      <link name='link'>
        <inertial>
          <mass>1</mass>
          <inertia>
            <ixx>0.145833</ixx>
            <ixy>0</ixy>
            <ixz>0</ixz>
            <iyy>0.145833</iyy>
            <iyz>0</iyz>
            <izz>0.125</izz>
          </inertia>
        </inertial>
        <collision name='collision'>
          <geometry>
            <cylinder>
              <radius>0.5</radius>
              <length>1</length>
            </cylinder>
          </geometry>
          <max_contacts>10</max_contacts>
          <surface>
            <contact>
              <ode/>
            </contact>
            <bounce/>
            <friction>
              <torsional>
                <ode/>
              </torsional>
              <ode/>
            </friction>
          </surface>
        </collision>
        <visual name='visual'>
          <geometry>
            <cylinder>
              <radius>0.5</radius>
              <length>1</length>
            </cylinder>
          </geometry>
          <material>
            <script>
              <name>Gazebo/Grey</name>
              <uri>file://media/materials/scripts/gazebo.material</uri>
            </script>
          </material>
        </visual>
        <self_collide>0</self_collide>
        <enable_wind>0</enable_wind>
        <kinematic>0</kinematic>
      </link>
    </model>
    <model name='unit_cylinder_7'>
      <pose frame=''>10.3886 8.45985 0.5 0 -0 0</pose>
      <link name='link'>
        <inertial>
          <mass>1</mass>
          <inertia>
            <ixx>0.145833</ixx>
            <ixy>0</ixy>
            <ixz>0</ixz>
            <iyy>0.145833</iyy>
            <iyz>0</iyz>
            <izz>0.125</izz>
          </inertia>
        </inertial>
        <collision name='collision'>
          <geometry>
            <cylinder>
              <radius>0.5</radius>
              <length>1</length>
            </cylinder>
          </geometry>
          <max_contacts>10</max_contacts>
          <surface>
            <contact>
              <ode/>
            </contact>
            <bounce/>
            <friction>
              <torsional>
                <ode/>
              </torsional>
              <ode/>
            </friction>
          </surface>
        </collision>
        <visual name='visual'>
          <geometry>
            <cylinder>
              <radius>0.5</radius>
              <length>1</length>
            </cylinder>
          </geometry>
          <material>
            <script>
              <name>Gazebo/Grey</name>
              <uri>file://media/materials/scripts/gazebo.material</uri>
            </script>
          </material>
        </visual>
        <self_collide>0</self_collide>
        <enable_wind>0</enable_wind>
        <kinematic>0</kinematic>
      </link>
    </model>
    <state world_name='default'>
      <sim_time>71 281000000</sim_time>
      <real_time>828 331935190</real_time>
      <wall_time>1699935690 241976144</wall_time>
      <iterations>71281</iterations>
      <model name='bunker'>
        <pose frame=''>-3.6e-05 0.000214 0.357688 -0.000652 -0.000122 -1.3e-05</pose>
        <scale>1 1 1</scale>
        <link name='robot_base'>
          <pose frame=''>-3.6e-05 0.000214 0.357688 -0.000652 -0.000122 -1.3e-05</pose>
          <velocity>0 -0 -0.010112 0 -0 0</velocity>
          <acceleration>3.5e-05 -0.000207 -10.1117 1.1e-05 -4.2e-05 -0</acceleration>
          <wrench>0 -0 -0.001011 0 -0 0</wrench>
        </link>
        <link name='wheel1.1_Link'>
          <pose frame=''>0.375506 0.349564 0.134456 1.57145 0 3.14158</pose>
          <velocity>-0 0 -0.010142 1e-06 -0 0</velocity>
          <acceleration>-4e-06 7.6e-05 -10.1425 0.001108 -0 0</acceleration>
          <wrench>-0 0 -0.001014 0 -0 0</wrench>
        </link>
        <link name='wheel1.2_Link'>
          <pose frame=''>0.290393 0.349527 0.076456 1.57145 0.000252 3.14158</pose>
          <velocity>-0 0 -0.010175 -0 -0 -0</velocity>
          <acceleration>-3e-06 5.5e-05 -10.1748 -6.2e-05 -0 -0</acceleration>
          <wrench>-0 0 -0.001017 0 -0 0</wrench>
        </link>
        <link name='wheel1.3_Link'>
          <pose frame=''>0.296009 0.349654 0.270496 1.57145 2e-05 3.14158</pose>
          <velocity>-0 0 -0.010157 -1e-06 0 0</velocity>
          <acceleration>-1.3e-05 4e-05 -10.1567 -0.000871 4e-06 0</acceleration>
          <wrench>-0 0 -0.001016 0 -0 0</wrench>
        </link>
        <link name='wheel1_Link'>
          <pose frame=''>0.444014 0.349625 0.228985 1.57145 0 3.14158</pose>
          <velocity>-0 0 -0.01009 0 -0 0</velocity>
          <acceleration>-1.2e-05 3e-05 -10.0901 -0.000434 0 0</acceleration>
          <wrench>-0 0 -0.001009 0 -0 0</wrench>
        </link>
        <link name='wheel2.1_Link'>
          <pose frame=''>0.375497 -0.349436 0.134913 1.57145 0 3.14158</pose>
          <velocity>-0 0 -0.009984 3e-06 -0 0</velocity>
          <acceleration>-9e-06 2.7e-05 -9.98423 0.003265 -0 0</acceleration>
          <wrench>-0 0 -0.000998 0 -0 0</wrench>
        </link>
        <link name='wheel2.2_Link'>
          <pose frame=''>0.290384 -0.349473 0.076913 1.57145 0.000151 3.14158</pose>
          <velocity>-0 0 -0.009852 1e-06 -0 0</velocity>
          <acceleration>-9e-06 2.8e-05 -9.85185 0.001312 -0 0</acceleration>
          <wrench>-0 0 -0.000985 0 -0 0</wrench>
        </link>
        <link name='wheel2.3_Link'>
          <pose frame=''>0.296 -0.349346 0.270954 1.57145 2.1e-05 3.14158</pose>
          <velocity>-0 0 -0.009712 2e-06 -0 0</velocity>
          <acceleration>-2e-05 3.3e-05 -9.71186 0.002099 -1e-06 0</acceleration>
          <wrench>-0 0 -0.000971 0 -0 0</wrench>
        </link>
        <link name='wheel2_Link'>
          <pose frame=''>0.444005 -0.349375 0.229443 1.57145 0 3.14158</pose>
          <velocity>-0 0 -0.009582 0 -0 0</velocity>
          <acceleration>-1.6e-05 3.4e-05 -9.58241 0.000471 -0 -1e-06</acceleration>
          <wrench>-0 0 -0.000958 0 -0 0</wrench>
        </link>
        <link name='wheel3.1_Link'>
          <pose frame=''>-0.231108 0.349537 0.080726 1.57145 -7.5e-05 3.14158</pose>
          <velocity>-0 0 -0.009482 -1e-06 0 0</velocity>
          <acceleration>-6e-06 3.2e-05 -9.4819 -0.000661 0 -1e-06</acceleration>
          <wrench>-0 0 -0.000948 0 -0 0</wrench>
        </link>
        <link name='wheel3.2_Link'>
          <pose frame=''>0.043887 0.349533 0.080759 1.57145 -9.3e-05 3.14158</pose>
          <velocity>-0 0 -0.009424 0 -0 0</velocity>
          <acceleration>-4e-06 2.9e-05 -9.42368 -0.000195 -0 -1e-06</acceleration>
          <wrench>-0 0 -0.000942 0 -0 0</wrench>
        </link>
        <link name='wheel3.3_Link'>
          <pose frame=''>-0.285991 0.349661 0.270429 1.57145 0 3.14158</pose>
          <velocity>-0 0 -0.009416 1e-06 -0 0</velocity>
          <acceleration>-1e-05 2.2e-05 -9.41615 0.000501 -0 0</acceleration>
          <wrench>-0 0 -0.000942 0 -0 0</wrench>
        </link>
        <link name='wheel3_Link'>
          <pose frame=''>-0.388718 0.295093 0.163642 1.57145 0 3.14158</pose>
          <velocity>0 0 -0.009461 0 -0 0</velocity>
          <acceleration>3e-06 5e-06 -9.46096 6e-06 -0 0</acceleration>
          <wrench>0 0 -0.000946 0 -0 0</wrench>
        </link>
        <link name='wheel4.1_Link'>
          <pose frame=''>-0.231117 -0.349463 0.081181 1.57145 -0.000101 3.14158</pose>
          <velocity>0 -0 -0.009552 -1e-06 -0 -0</velocity>
          <acceleration>1.4e-05 -1.6e-05 -9.5519 -0.001131 -0 -1e-06</acceleration>
          <wrench>0 -0 -0.000955 0 -0 0</wrench>
        </link>
        <link name='wheel4.2_Link'>
          <pose frame=''>0.043878 -0.349467 0.081214 1.57145 -0.001464 3.14158</pose>
          <velocity>0 -0 -0.009677 -1e-06 0 0</velocity>
          <acceleration>1.8e-05 -3.8e-05 -9.67731 -0.001329 -0 -1e-06</acceleration>
          <wrench>0 -0 -0.000968 0 -0 0</wrench>
        </link>
        <link name='wheel4.3_Link'>
          <pose frame=''>-0.286 -0.349339 0.270883 1.57145 0 3.14158</pose>
          <velocity>0 -0 -0.00982 -2e-06 0 0</velocity>
          <acceleration>1.2e-05 -6.2e-05 -9.82018 -0.002236 0 0</acceleration>
          <wrench>0 -0 -0.000982 0 -0 0</wrench>
        </link>
        <link name='wheel4_Link'>
          <pose frame=''>-0.388726 -0.294907 0.164024 1.57145 0 3.14158</pose>
          <velocity>0 -0 -0.009962 0 -0 0</velocity>
          <acceleration>2.3e-05 -8.7e-05 -9.96171 -3e-05 0 0</acceleration>
          <wrench>0 -0 -0.000996 0 -0 0</wrench>
        </link>
      </model>
      <model name='ground_plane'>
        <pose frame=''>0 0 0 0 -0 0</pose>
        <scale>1 1 1</scale>
        <link name='link'>
          <pose frame=''>0 0 0 0 -0 0</pose>
          <velocity>0 0 0 0 -0 0</velocity>
          <acceleration>0 0 0 0 -0 0</acceleration>
          <wrench>0 0 0 0 -0 0</wrench>
        </link>
      </model>
      <model name='unit_cylinder'>
        <pose frame=''>2.46552 1.50285 0.499993 -3e-06 -4e-06 -0</pose>
        <scale>1 1 1</scale>
        <link name='link'>
          <pose frame=''>2.46552 1.50285 0.499993 -3e-06 -4e-06 -0</pose>
          <velocity>0 0 0 0 -0 0</velocity>
          <acceleration>0 0 -9.8 0 -0 0</acceleration>
          <wrench>0 0 -9.8 0 -0 0</wrench>
        </link>
      </model>
      <model name='unit_cylinder_0'>
        <pose frame=''>2.39133 4.98227 0.499997 3e-06 4e-06 -0</pose>
        <scale>1 1 1</scale>
        <link name='link'>
          <pose frame=''>2.39133 4.98227 0.499997 3e-06 4e-06 -0</pose>
          <velocity>0 0 0 0 -0 0</velocity>
          <acceleration>0 0 -9.8 0 -0 0</acceleration>
          <wrench>0 0 -9.8 0 -0 0</wrench>
        </link>
      </model>
      <model name='unit_cylinder_1'>
        <pose frame=''>6.43858 1.49488 0.499993 -3e-06 -4e-06 -0</pose>
        <scale>1 1 1</scale>
        <link name='link'>
          <pose frame=''>6.43858 1.49488 0.499993 -3e-06 -4e-06 -0</pose>
          <velocity>0 0 0 0 -0 0</velocity>
          <acceleration>0 0 -9.8 0 -0 0</acceleration>
          <wrench>0 0 -9.8 0 -0 0</wrench>
        </link>
      </model>
      <model name='unit_cylinder_2'>
        <pose frame=''>10.5304 1.45072 0.499993 -3e-06 -4e-06 -0</pose>
        <scale>1 1 1</scale>
        <link name='link'>
          <pose frame=''>10.5304 1.45072 0.499993 -3e-06 -4e-06 -0</pose>
          <velocity>0 0 0 0 -0 0</velocity>
          <acceleration>0 0 -9.8 0 -0 0</acceleration>
          <wrench>0 0 -9.8 0 -0 0</wrench>
        </link>
      </model>
      <model name='unit_cylinder_3'>
        <pose frame=''>6.50042 5.02827 0.499997 3e-06 4e-06 -0</pose>
        <scale>1 1 1</scale>
        <link name='link'>
          <pose frame=''>6.50042 5.02827 0.499997 3e-06 4e-06 -0</pose>
          <velocity>0 0 0 0 -0 0</velocity>
          <acceleration>0 0 -9.8 0 -0 0</acceleration>
          <wrench>0 0 -9.8 0 -0 0</wrench>
        </link>
      </model>
      <model name='unit_cylinder_4'>
        <pose frame=''>10.4721 5.01715 0.499997 3e-06 4e-06 -0</pose>
        <scale>1 1 1</scale>
        <link name='link'>
          <pose frame=''>10.4721 5.01715 0.499997 3e-06 4e-06 -0</pose>
          <velocity>0 0 0 0 -0 0</velocity>
          <acceleration>0 0 -9.8 0 -0 0</acceleration>
          <wrench>0 0 -9.8 0 -0 0</wrench>
        </link>
      </model>
      <model name='unit_cylinder_5'>
        <pose frame=''>2.4295 8.37947 0.499993 -3e-06 -4e-06 -0</pose>
        <scale>1 1 1</scale>
        <link name='link'>
          <pose frame=''>2.4295 8.37947 0.499993 -3e-06 -4e-06 -0</pose>
          <velocity>0 0 0 0 -0 0</velocity>
          <acceleration>0 0 -9.8 0 -0 0</acceleration>
          <wrench>0 0 -9.8 0 -0 0</wrench>
        </link>
      </model>
      <model name='unit_cylinder_6'>
        <pose frame=''>6.43133 8.38113 0.499997 3e-06 4e-06 -0</pose>
        <scale>1 1 1</scale>
        <link name='link'>
          <pose frame=''>6.43133 8.38113 0.499997 3e-06 4e-06 -0</pose>
          <velocity>0 0 0 0 -0 0</velocity>
          <acceleration>0 0 -9.8 0 -0 0</acceleration>
          <wrench>0 0 -9.8 0 -0 0</wrench>
        </link>
      </model>
      <model name='unit_cylinder_7'>
        <pose frame=''>10.3886 8.45985 0.499997 3e-06 4e-06 -0</pose>
        <scale>1 1 1</scale>
        <link name='link'>
          <pose frame=''>10.3886 8.45985 0.499997 3e-06 4e-06 -0</pose>
          <velocity>0 0 0 0 -0 0</velocity>
          <acceleration>0 0 -9.8 0 -0 0</acceleration>
          <wrench>0 0 -9.8 0 -0 0</wrench>
        </link>
      </model>
      <light name='sun'>
        <pose frame=''>0 0 10 0 -0 0</pose>
      </light>
    </state>
    <gui fullscreen='0'>
      <camera name='user_camera'>
        <pose frame=''>-9.64569 5.09591 15.7171 0 0.807643 -0.231806</pose>
        <view_controller>orbit</view_controller>
        <projection_type>perspective</projection_type>
      </camera>
    </gui>
  </world>
</sdf>
